{"type":"meta","schema_version":"ndjson.v0","symbol":"BTCUSDT","stream":"btcusdt@depth","start_unix_ms":1767174232172,"start_utc":"2025-12-31T09:43:52.172395+00:00","source":"binance_spot_ws"}
{"result":null,"id":1}
{"e":"depthUpdate","E":1767174233014,"s":"BTCUSDT","U":84208125321,"u":84208125425,"b":[["88660.98000000","4.11288000"],["88655.76000000","0.00000000"],["88655.75000000","0.01533000"],["88655.74000000","0.00000000"],["88655.73000000","0.00000000"],["88655.68000000","0.00059000"],["88655.13000000","0.00098000"],["88655.11000000","0.05148000"],["88653.16000000","0.00012000"],["88650.37000000","0.00006000"],["88650.31000000","0.04218000"],["88649.35000000","0.01129000"],["88635.93000000","0.00000000"],["88635.92000000","0.00000000"],["88635.91000000","0.00000000"],["88635.90000000","0.00000000"],["88635.89000000","0.00000000"],["88635.88000000","0.05648000"],["88588.84000000","0.00018000"],["88540.30000000","0.01846000"],["86770.91000000","0.00000000"],["79794.89000000","0.00238000"],["79794.00000000","0.00010000"],["70929.00000000","0.00000000"],["70928.79000000","0.00028000"],["42000.00000000","16.04102000"],["31917.95000000","0.01159000"]],"a":[["88660.99000000","5.31025000"],["88710.00000000","0.14230000"]]}
{"e":"depthUpdate","E":1767174234014,"s":"BTCUSDT","U":84208125426,"u":84208125683,"b":[["88660.98000000","4.11792000"],["88660.97000000","0.08861000"],["88655.76000000","0.00012000"],["88655.75000000","0.02891000"],["88655.12000000","0.04018000"],["88655.11000000","0.00000000"],["88654.97000000","0.00000000"],["88654.84000000","0.00000000"],["88654.83000000","0.00000000"],["88654.78000000","0.00057000"],["88654.77000000","0.00300000"],["88654.69000000","0.00000000"],["88654.54000000","0.00000000"],["88654.53000000","0.00000000"],["88654.32000000","0.00012000"],["88654.31000000","0.05213000"],["88653.16000000","0.00000000"],["88651.98000000","0.01518000"],["88651.59000000","0.00000000"],["88650.37000000","0.00000000"],["88650.36000000","0.07546000"],["88650.35000000","0.00198000"],["88650.31000000","0.04206000"],["88649.59000000","0.00000000"],["88649.52000000","0.37272000"],["88649.37000000","0.04206000"],["88649.35000000","0.01123000"],["88636.02000000","0.00000000"],["88636.01000000","0.00000000"],["88636.00000000","0.00180000"],["88635.99000000","0.05648000"],["88635.88000000","0.00000000"],["88635.87000000","0.00000000"],["88635.86000000","0.00000000"],["88635.85000000","0.00000000"],["88630.75000000","0.00000000"],["88621.06000000","0.00000000"],["88617.07000000","0.40676000"],["88368.57000000","0.01767000"],["88000.00000000","10.12834000"],["79794.89000000","0.00252000"],["79794.00000000","0.00010000"],["70928.79000000","0.00028000"]],"a":[["88660.99000000","5.30881000"],["88667.19000000","0.00045000"],["88671.62000000","0.00180000"]]}
{"e":"depthUpdate","E":1767174235014,"s":"BTCUSDT","U":84208125684,"u":84208125836,"b":[["88660.98000000","4.11442000"],["88660.97000000","0.08867000"],["88655.76000000","0.00000000"],["88655.75000000","0.01533000"],["88655.68000000","0.00053000"],["88655.13000000","0.00000000"],["88655.12000000","0.00093000"],["88654.77000000","0.00306000"],["88654.32000000","0.00000000"],["88654.31000000","0.00000000"],["88654.10000000","0.00000000"],["88654.09000000","0.00030000"],["88654.08000000","0.05178000"],["88654.00000000","0.01228000"],["88653.16000000","0.00012000"],["88650.37000000","0.00006000"],["88650.31000000","0.04206000"],["88649.37000000","0.04200000"],["88635.99000000","0.00000000"],["88635.98000000","0.00000000"],["88635.97000000","0.00000000"],["88635.96000000","0.00000000"],["88635.95000000","0.05648000"],["86411.43000000","0.00000000"],["79794.89000000","0.00238000"],["79794.00000000","0.00010000"],["70929.00000000","0.00000000"],["70928.79000000","0.00028000"],["42000.00000000","16.04002000"]],"a":[["88660.99000000","5.30565000"],["88701.47000000","0.08455000"],["88701.48000000","0.00000000"],["89000.00000000","11.31787000"]]}
{"e":"depthUpdate","E":1767174236015,"s":"BTCUSDT","U":84208125837,"u":84208125933,"b":[["88660.98000000","4.09437000"],["88655.75000000","0.01533000"],["88654.09000000","0.00024000"],["88654.08000000","0.05190000"],["88635.95000000","0.00000000"],["88635.94000000","0.00000000"],["88635.93000000","0.00000000"],["88635.91000000","0.00000000"],["88635.90000000","0.00000000"],["88635.89000000","0.05648000"],["88620.38000000","0.00000000"],["88000.00000000","10.12853000"],["87160.98000000","0.00000000"],["87065.09000000","0.00000000"],["79794.89000000","0.00252000"],["79794.00000000","0.00010000"],["70929.00000000","0.00000000"],["70928.79000000","0.00028000"],["31917.95000000","0.01178000"]],"a":[["88660.99000000","5.29965000"],["88701.59000000","0.05452000"],["88726.18000000","0.00000000"],["88735.97000000","0.00717000"],["88737.36000000","0.00000000"],["88770.52000000","0.04200000"]]}
{"e":"depthUpdate","E":1767174237014,"s":"BTCUSDT","U":84208125934,"u":84208126205,"b":[["88660.98000000","4.10421000"],["88660.97000000","0.08855000"],["88660.96000000","0.00039000"],["88660.95000000","0.32660000"],["88655.75000000","0.00000000"],["88655.70000000","0.00259000"],["88654.77000000","0.00300000"],["88654.09000000","0.00006000"],["88654.08000000","0.00000000"],["88654.02000000","0.00000000"],["88654.01000000","0.00000000"],["88653.62000000","0.00000000"],["88653.61000000","0.00000000"],["88653.15000000","0.24621000"],["88653.08000000","0.00000000"],["88653.07000000","0.00000000"],["88653.06000000","0.00012000"],["88652.41000000","0.00000000"],["88652.34000000","0.00000000"],["88651.98000000","0.01518000"],["88651.73000000","0.00047000"],["88651.60000000","0.00000000"],["88651.59000000","0.00000000"],["88650.37000000","0.00012000"],["88650.32000000","0.00006000"],["88650.31000000","0.04218000"],["88650.27000000","0.03506000"],["88650.26000000","0.00000000"],["88649.52000000","0.00000000"],["88649.46000000","0.37272000"],["88649.43000000","0.10506000"],["88649.39000000","0.00000000"],["88649.38000000","0.03856000"],["88649.37000000","0.04200000"],["88649.35000000","0.00000000"],["88647.63000000","0.00000000"],["88647.43000000","0.01151000"],["88641.35000000","0.00000000"],["88638.39000000","0.00346000"],["88636.83000000","0.00000000"],["88635.89000000","0.00000000"],["88635.88000000","0.00000000"],["88635.10000000","0.05648000"],["88635.09000000","0.00000000"],["88635.08000000","0.00000000"],["88635.06000000","0.00000000"],["88635.05000000","0.00000000"],["88634.47000000","0.00000000"],["88633.14000000","0.07228000"],["88540.30000000","0.02266000"],["88458.94000000","0.00000000"],["87065.08000000","0.00574000"],["81568.11000000","0.00000000"],["79794.89000000","0.00238000"],["79794.00000000","0.00010000"],["70928.79000000","0.00028000"],["33000.00000000","6.20342000"],["31917.95000000","0.01197000"]],"a":[["88660.99000000","5.29654000"],["88661.00000000","0.00270000"],["88672.65000000","0.00000000"],["88677.72000000","0.00000000"],["88679.61000000","0.06492000"],["88682.28000000","0.00346000"],["88683.57000000","0.00000000"],["88683.96000000","0.00000000"],["88684.23000000","0.00000000"],["88696.07000000","0.05084000"],["88701.58000000","0.01183000"],["88711.74000000","0.00000000"],["88720.84000000","0.04200000"],["88724.82000000","0.02998000"],["88757.47000000","0.06000000"],["88761.75000000","0.00000000"],["88770.52000000","0.00000000"],["88845.24000000","0.00000000"],["89179.71000000","0.21928000"],["89182.63000000","0.00075000"]]}
{"e":"depthUpdate","E":1767174238014,"s":"BTCUSDT","U":84208126206,"u":84208126348,"b":[["88660.98000000","4.09194000"],["88653.15000000","0.24621000"],["88653.06000000","0.00000000"],["88653.05000000","0.00000000"],["88652.15000000","0.00012000"],["88652.14000000","0.05275000"],["88650.32000000","0.00000000"],["88650.27000000","0.03506000"],["88649.37000000","0.04200000"],["88644.82000000","0.00000000"],["88635.19000000","0.05648000"],["88635.18000000","0.00000000"],["88635.17000000","0.00000000"],["88635.15000000","0.00000000"],["88635.14000000","0.00000000"],["88635.13000000","0.00000000"],["88635.12000000","0.00000000"],["88635.11000000","0.00000000"],["88635.10000000","0.00000000"],["88459.08000000","4.93785000"],["88000.00000000","10.12904000"],["79794.89000000","0.00252000"],["79794.00000000","0.00010000"],["70929.00000000","0.00000000"],["70928.79000000","0.00028000"]],"a":[["88660.99000000","5.59073000"],["88681.33000000","0.00347000"],["88682.28000000","0.00000000"],["88716.41000000","0.04620000"],["88721.69000000","0.00000000"],["88732.63000000","0.07496000"],["88766.04000000","0.00000000"],["88769.17000000","0.04200000"],["88845.12000000","5.04372000"],["89179.71000000","0.00000000"],["89182.63000000","0.22003000"]]}
{"e":"depthUpdate","E":1767174239014,"s":"BTCUSDT","U":84208126349,"u":84208126546,"b":[["88660.98000000","3.68621000"],["88660.97000000","0.08855000"],["88653.15000000","0.14035000"],["88652.15000000","0.00000000"],["88652.14000000","0.00000000"],["88651.00000000","0.01388000"],["88650.91000000","0.00190000"],["88650.72000000","0.00000000"],["88650.64000000","0.00000000"],["88650.63000000","0.00000000"],["88650.32000000","0.00006000"],["88650.27000000","0.03518000"],["88649.93000000","0.00000000"],["88649.69000000","0.03385000"],["88649.46000000","0.00000000"],["88649.37000000","0.04206000"],["88647.51000000","0.37273000"],["88644.01000000","0.00000000"],["88643.54000000","0.00000000"],["88642.37000000","0.00564000"],["88641.34000000","0.05646000"],["88635.27000000","0.05648000"],["88635.26000000","0.00000000"],["88635.25000000","0.00000000"],["88635.23000000","0.00000000"],["88635.21000000","0.00000000"],["88635.20000000","0.00000000"],["88635.19000000","0.00000000"],["88634.48000000","0.00000000"],["88634.18000000","0.04516000"],["88604.16000000","0.00000000"],["88603.88000000","0.00000000"],["88603.52000000","0.00600000"],["88598.62000000","0.03098000"],["88595.74000000","0.00000000"],["88595.46000000","0.00000000"],["88595.10000000","0.04360000"],["88587.74000000","0.03052000"],["88582.69000000","0.00147000"],["79794.89000000","0.00238000"],["79794.00000000","0.00010000"],["70928.79000000","0.00028000"],["60000.00000000","227.86147000"],["31917.95000000","0.01216000"]],"a":[["88660.99000000","5.54659000"],["88664.95000000","0.05039000"],["88665.53000000","0.00677000"],["88665.54000000","0.00000000"],["88665.57000000","0.00000000"],["88681.06000000","0.00564000"],["88681.57000000","0.00000000"],["88681.58000000","0.04516000"],["88682.15000000","0.02823000"],["88683.54000000","0.00000000"],["88683.55000000","0.00000000"],["88719.51000000","0.04200000"],["88728.14000000","0.00147000"],["88735.98000000","0.00000000"],["88736.06000000","0.00000000"],["88736.22000000","0.04360000"],["88744.40000000","0.00000000"],["88744.49000000","0.00000000"],["88744.65000000","0.00600000"],["88769.17000000","0.00000000"],["88776.98000000","0.04200000"]]}
{"e":"depthUpdate","E":1767174240014,"s":"BTCUSDT","U":84208126547,"u":84208126896,"b":[["88660.98000000","3.88309000"],["88660.97000000","0.08855000"],["88660.95000000","0.32660000"],["88654.77000000","0.00300000"],["88654.02000000","0.00000000"],["88654.01000000","0.00000000"],["88653.82000000","0.00000000"],["88653.81000000","0.00000000"],["88653.76000000","0.00000000"],["88653.75000000","0.00000000"],["88653.67000000","0.00000000"],["88653.26000000","0.00000000"],["88653.15000000","0.24576000"],["88652.58000000","0.00000000"],["88652.46000000","0.00000000"],["88652.24000000","0.00000000"],["88652.19000000","0.00000000"],["88652.18000000","0.00000000"],["88652.14000000","0.00000000"],["88651.98000000","0.01518000"],["88651.73000000","0.00053000"],["88651.33000000","0.00012000"],["88651.32000000","0.00012000"],["88651.31000000","0.00000000"],["88651.00000000","0.01388000"],["88650.91000000","0.00190000"],["88650.67000000","0.00000000"],["88650.66000000","0.00000000"],["88650.59000000","0.00000000"],["88650.58000000","0.00006000"],["88650.37000000","0.00012000"],["88650.32000000","0.00000000"],["88650.31000000","0.04218000"],["88650.27000000","0.03506000"],["88650.21000000","0.00000000"],["88650.00000000","0.01746000"],["88649.38000000","0.03856000"],["88649.37000000","0.04200000"],["88649.31000000","0.37272000"],["88649.04000000","0.00250000"],["88647.51000000","0.00000000"],["88643.91000000","0.00564000"],["88642.37000000","0.00000000"],["88635.34000000","0.05648000"],["88635.33000000","0.00000000"],["88635.32000000","0.00000000"],["88635.31000000","0.00000000"],["88635.30000000","0.00000000"],["88635.29000000","0.00000000"],["88635.28000000","0.00000000"],["88635.27000000","0.00000000"],["88630.54000000","0.03198000"],["88609.11000000","0.00000000"],["88603.52000000","0.00000000"],["88603.45000000","0.00600000"],["88595.10000000","0.00000000"],["88595.03000000","0.04360000"],["88590.00000000","0.00180000"],["88568.15000000","0.26656000"],["88000.00000000","10.12868000"],["79794.89000000","0.00252000"],["79794.00000000","0.00010000"],["70928.79000000","0.00028000"]],"a":[["88660.99000000","5.53380000"],["88664.95000000","0.05039000"],["88665.49000000","0.00643000"],["88665.51000000","0.00000000"],["88665.53000000","0.00000000"],["88673.27000000","0.05646000"],["88681.06000000","0.00000000"],["88681.32000000","0.00564000"],["88716.40000000","0.04200000"],["88721.66000000","0.00000000"],["88721.67000000","0.00014000"],["88721.68000000","0.00000000"],["88721.78000000","0.00234000"],["88723.80000000","0.00000000"],["88731.99000000","0.03098000"],["88735.24000000","0.00717000"],["88735.97000000","0.00000000"],["88736.22000000","0.00000000"],["88736.29000000","0.04360000"],["88744.65000000","0.00000000"],["88744.71000000","0.00600000"],["88756.83000000","0.10494000"],["88776.98000000","0.00000000"]]}
{"e":"depthUpdate","E":1767174241014,"s":"BTCUSDT","U":84208126897,"u":84208127132,"b":[["88660.98000000","3.89450000"],["88660.95000000","0.32660000"],["88656.55000000","0.00000000"],["88655.70000000","0.00000000"],["88655.68000000","0.00062000"],["88654.77000000","0.00300000"],["88654.02000000","0.00000000"],["88654.01000000","0.00000000"],["88654.00000000","0.01228000"],["88653.79000000","0.00000000"],["88653.78000000","0.00000000"],["88653.15000000","0.24578000"],["88651.98000000","0.01518000"],["88651.73000000","0.00047000"],["88651.33000000","0.00000000"],["88651.32000000","0.00000000"],["88651.00000000","0.01388000"],["88650.91000000","0.00190000"],["88650.43000000","0.00000000"],["88650.42000000","0.00000000"],["88650.37000000","0.00012000"],["88650.32000000","0.00006000"],["88650.31000000","0.04218000"],["88650.27000000","0.03524000"],["88650.24000000","0.05068000"],["88649.38000000","0.03856000"],["88649.37000000","0.04206000"],["88649.31000000","0.00000000"],["88649.29000000","0.37272000"],["88649.04000000","0.00256000"],["88648.76000000","0.02937000"],["88647.40000000","0.00000000"],["88644.60000000","0.00250000"],["88643.91000000","0.00000000"],["88642.39000000","0.00564000"],["88642.38000000","0.00000000"],["88638.73000000","0.00000000"],["88635.76000000","0.03597000"],["88635.35000000","0.00000000"],["88635.34000000","0.05648000"],["88630.54000000","0.06396000"],["88620.93000000","0.00006000"],["88616.43000000","1.89381000"],["88606.14000000","0.04700000"],["88597.55000000","0.08465000"],["88597.54000000","0.00000000"],["88590.00000000","0.14180000"],["88461.29000000","0.03198000"],["88435.01000000","0.00000000"],["88385.22000000","0.03298000"],["88381.37000000","0.03298000"],["88377.43000000","0.03298000"],["88372.36000000","0.03298000"],["88364.95000000","0.03298000"],["88359.49000000","0.00000000"],["88355.35000000","0.00000000"],["88351.40000000","0.00000000"],["88346.21000000","0.00000000"],["88338.73000000","0.00000000"],["87000.00000000","70.43380000"],["79794.89000000","0.00238000"],["79794.00000000","0.00010000"],["70929.00000000","0.00000000"],["70928.79000000","0.00028000"],["33000.00000000","6.20342000"]],"a":[["88660.99000000","5.54163000"],["88661.00000000","0.00276000"],["88664.22000000","0.04080000"],["88664.29000000","0.04521000"],["88664.53000000","0.04290000"],["88664.70000000","0.05639000"],["88664.77000000","0.10996000"],["88664.95000000","0.05027000"],["88665.40000000","0.01127000"],["88667.04000000","0.02255000"],["89179.71000000","0.21928000"],["89182.63000000","0.00075000"]]}
{"e":"depthUpdate","E":1767174242014,"s":"BTCUSDT","U":84208127133,"u":84208127314,"b":[["88660.98000000","3.92794000"],["88660.96000000","0.00045000"],["88660.95000000","0.32660000"],["88655.70000000","0.00259000"],["88655.68000000","0.00047000"],["88655.12000000","0.00006000"],["88654.77000000","0.00300000"],["88654.04000000","0.00000000"],["88654.03000000","0.00000000"],["88654.02000000","0.00000000"],["88653.15000000","0.19859000"],["88652.17000000","0.00012000"],["88652.16000000","0.05039000"],["88651.29000000","0.00000000"],["88650.37000000","0.00012000"],["88650.32000000","0.00000000"],["88650.31000000","0.04218000"],["88650.27000000","0.03518000"],["88650.24000000","0.00000000"],["88649.37000000","0.04206000"],["88649.04000000","0.00256000"],["88644.60000000","0.00000000"],["88643.54000000","0.00564000"],["88642.39000000","0.00000000"],["88638.39000000","0.00000000"],["88635.97000000","0.00000000"],["88635.95000000","0.00000000"],["88635.94000000","0.00000000"],["88635.93000000","0.00000000"],["88635.92000000","0.05648000"],["88635.34000000","0.00000000"],["88635.32000000","0.00000000"],["88635.31000000","0.00000000"],["88635.29000000","0.00000000"],["88635.28000000","0.00000000"],["88590.00000000","0.00180000"],["88313.89000000","0.03198000"],["88313.48000000","0.03198000"],["88288.30000000","0.00000000"],["88287.78000000","0.00000000"],["88000.00000000","10.12773000"],["81568.11000000","0.00013000"],["79794.89000000","0.00252000"],["79794.00000000","0.00010000"],["70928.79000000","0.00028000"]],"a":[["88660.99000000","5.53863000"],["88662.30000000","0.22631000"],["88662.31000000","0.00000000"],["88662.32000000","0.00006000"],["88664.70000000","0.05651000"],["89179.71000000","0.00000000"],["89182.63000000","0.22003000"]]}
{"e":"depthUpdate","E":1767174243014,"s":"BTCUSDT","U":84208127315,"u":84208127623,"b":[["88660.98000000","3.86020000"],["88660.97000000","0.08855000"],["88660.95000000","0.32660000"],["88654.78000000","0.00147000"],["88654.77000000","0.00300000"],["88654.02000000","0.00012000"],["88654.01000000","0.01956000"],["88654.00000000","0.01228000"],["88653.86000000","0.00012000"],["88653.85000000","0.00000000"],["88653.67000000","0.00000000"],["88653.64000000","0.00000000"],["88653.63000000","0.00000000"],["88653.61000000","0.00000000"],["88653.46000000","0.00000000"],["88653.23000000","0.00000000"],["88653.22000000","0.00012000"],["88653.21000000","0.00000000"],["88653.20000000","0.00000000"],["88653.16000000","0.00006000"],["88653.15000000","0.14035000"],["88653.02000000","0.00000000"],["88653.01000000","0.00007000"],["88653.00000000","0.00000000"],["88652.87000000","0.00000000"],["88652.86000000","0.00000000"],["88652.82000000","0.00000000"],["88652.63000000","0.00000000"],["88652.62000000","0.00000000"],["88652.58000000","0.00000000"],["88652.47000000","0.05116000"],["88652.36000000","0.00000000"],["88652.17000000","0.00000000"],["88652.16000000","0.00000000"],["88650.37000000","0.00000000"],["88650.32000000","0.00000000"],["88650.27000000","0.03506000"],["88649.29000000","0.00000000"],["88649.04000000","0.00256000"],["88648.76000000","0.02943000"],["88647.45000000","0.37273000"],["88643.90000000","0.63380000"],["88643.54000000","0.00000000"],["88643.42000000","1.86283000"],["88642.37000000","0.00564000"],["88638.67000000","0.67674000"],["88636.04000000","0.05648000"],["88635.92000000","0.00000000"],["88635.90000000","0.00000000"],["88635.87000000","0.00000000"],["88635.85000000","0.00000000"],["88634.90000000","0.00000000"],["88634.86000000","0.00000000"],["88634.84000000","0.00000000"],["88580.58000000","0.03098000"],["88471.15000000","0.00000000"],["88454.55000000","0.03198000"],["88311.83000000","0.00000000"],["88311.71000000","0.00000000"],["88311.30000000","0.00000000"],["88311.09000000","0.03198000"],["88310.10000000","0.03198000"],["88309.56000000","0.03198000"],["81568.11000000","0.00000000"],["79794.89000000","0.00238000"],["79794.00000000","0.00010000"],["70929.00000000","0.00000000"],["70928.79000000","0.00028000"],["42000.00000000","16.04102000"]],"a":[["88660.99000000","5.54027000"],["88661.00000000","0.00270000"],["88665.44000000","0.00644000"],["88665.45000000","0.00000000"],["88665.49000000","0.00000000"],["88681.33000000","0.00000000"],["88692.01000000","0.00000000"],["88774.27000000","0.02735000"],["88777.02000000","0.00000000"],["88786.64000000","0.00000000"],["88791.33000000","0.10940000"],["89179.71000000","0.21928000"],["89182.63000000","0.00075000"]]}
{"e":"depthUpdate","E":1767174244014,"s":"BTCUSDT","U":84208127624,"u":84208127888,"b":[["88660.98000000","3.88744000"],["88660.97000000","0.08861000"],["88660.95000000","0.32660000"],["88655.68000000","0.00053000"],["88655.27000000","0.00000000"],["88654.96000000","0.00012000"],["88654.95000000","0.02132000"],["88654.94000000","0.05092000"],["88654.80000000","0.00000000"],["88654.79000000","0.00000000"],["88654.78000000","0.00147000"],["88654.77000000","0.00300000"],["88654.70000000","0.00000000"],["88654.69000000","0.00000000"],["88654.14000000","0.00000000"],["88654.02000000","0.00000000"],["88654.01000000","0.00000000"],["88654.00000000","0.01228000"],["88653.86000000","0.00000000"],["88653.57000000","0.00000000"],["88653.22000000","0.00000000"],["88653.16000000","0.00012000"],["88653.15000000","0.23056000"],["88652.48000000","0.00000000"],["88652.47000000","0.00000000"],["88650.37000000","0.00000000"],["88650.32000000","0.00000000"],["88650.31000000","0.04206000"],["88650.27000000","0.03506000"],["88649.44000000","0.37272000"],["88649.37000000","0.04206000"],["88649.04000000","0.00250000"],["88648.76000000","0.02937000"],["88647.45000000","0.00000000"],["88636.04000000","0.00000000"],["88636.03000000","0.00000000"],["88636.02000000","0.00000000"],["88636.01000000","0.05648000"],["88590.00000000","0.14180000"],["88555.22000000","0.00282000"],["88555.21000000","0.00000000"],["88466.68000000","0.00112000"],["88466.67000000","0.00000000"],["88459.20000000","5.04882000"],["88459.08000000","0.00000000"],["88420.69000000","0.01767000"],["88368.57000000","0.00000000"],["88311.57000000","0.00100000"],["88000.00000000","10.12759000"],["87795.10000000","0.00196000"],["79794.89000000","0.00252000"],["79794.00000000","0.00010000"],["70929.00000000","0.00000000"],["70928.79000000","0.00028000"],["31917.95000000","0.01235000"]],"a":[["88660.99000000","5.52794000"],["88677.12000000","0.00346000"],["88735.24000000","0.00000000"],["88738.37000000","0.09712000"],["88845.00000000","4.95900000"],["88845.12000000","0.00000000"],["89179.71000000","0.00000000"],["89182.63000000","0.22003000"],["89426.15000000","0.00192000"]]}
{"e":"depthUpdate","E":1767174245014,"s":"BTCUSDT","U":84208127889,"u":84208128267,"b":[["88660.98000000","3.70274000"],["88660.97000000","0.08855000"],["88660.95000000","0.32660000"],["88655.68000000","0.00047000"],["88654.96000000","0.00000000"],["88654.95000000","0.00000000"],["88654.94000000","0.00000000"],["88653.15000000","0.16644000"],["88653.05000000","0.00000000"],["88652.59000000","0.00000000"],["88652.58000000","0.00000000"],["88652.35000000","0.00000000"],["88652.34000000","0.00000000"],["88652.02000000","0.00000000"],["88652.01000000","0.00006000"],["88651.98000000","0.01524000"],["88651.94000000","0.00012000"],["88651.93000000","0.05102000"],["88651.86000000","0.00000000"],["88651.73000000","0.00047000"],["88651.69000000","0.00000000"],["88651.45000000","0.00000000"],["88651.44000000","0.00000000"],["88651.17000000","0.00000000"],["88651.13000000","0.00000000"],["88651.12000000","0.00000000"],["88651.00000000","0.01388000"],["88650.97000000","0.00000000"],["88650.96000000","0.00000000"],["88650.91000000","0.00190000"],["88650.81000000","0.00000000"],["88650.80000000","0.00000000"],["88650.64000000","0.00000000"],["88650.63000000","0.00000000"],["88650.37000000","0.00012000"],["88650.31000000","0.04218000"],["88650.27000000","0.03506000"],["88650.12000000","0.00000000"],["88650.00000000","0.01746000"],["88649.69000000","0.00000000"],["88649.66000000","0.03385000"],["88649.54000000","0.00000000"],["88649.44000000","0.00000000"],["88649.04000000","0.00256000"],["88648.76000000","0.02937000"],["88647.92000000","0.00000000"],["88647.55000000","0.37273000"],["88647.43000000","0.00000000"],["88646.50000000","0.00000000"],["88646.01000000","0.00000000"],["88645.71000000","0.01145000"],["88644.01000000","0.00000000"],["88643.90000000","0.10454000"],["88643.42000000","0.00000000"],["88642.37000000","0.00564000"],["88638.67000000","0.00000000"],["88636.01000000","0.00000000"],["88636.00000000","0.00180000"],["88634.52000000","0.05648000"],["88634.51000000","0.00000000"],["88633.14000000","0.00000000"],["88628.11000000","0.06322000"],["88587.87000000","0.00000000"],["88555.22000000","0.00000000"],["88555.21000000","0.00282000"],["88466.68000000","0.00000000"],["88466.67000000","0.00112000"],["88420.69000000","0.00000000"],["88310.89000000","0.00000000"],["88309.56000000","0.00000000"],["88218.79000000","0.00250000"],["88214.55000000","0.00000000"],["87795.10000000","0.00000000"],["86500.00000000","44.95327000"],["79794.89000000","0.00238000"],["79794.00000000","0.00010000"],["70928.79000000","0.00028000"],["42000.00000000","16.04002000"]],"a":[["88660.99000000","5.52500000"],["88661.00000000","0.00270000"],["88661.82000000","0.01139000"],["88662.27000000","0.00012000"],["88662.28000000","0.42852000"],["88662.29000000","0.67686000"],["88662.30000000","0.00000000"],["88662.32000000","0.00000000"],["88664.70000000","0.05639000"],["88665.43000000","0.00640000"],["88665.44000000","0.00000000"],["88671.71000000","0.00564000"],["88672.64000000","0.00000000"],["88674.93000000","0.00000000"],["88679.61000000","0.06792000"],["88681.32000000","0.00000000"],["88681.58000000","0.00000000"],["88681.99000000","0.00564000"],["88683.55000000","0.04516000"],["88684.18000000","0.00000000"],["88685.81000000","0.00000000"],["88685.82000000","0.00300000"],["89426.15000000","0.00000000"]]}
{"e":"depthUpdate","E":1767174246014,"s":"BTCUSDT","U":84208128268,"u":84208128420,"b":[["88660.98000000","3.57247000"],["88651.98000000","0.01518000"],["88651.94000000","0.00000000"],["88651.93000000","0.00000000"],["88651.84000000","0.00000000"],["88651.73000000","0.00053000"],["88651.60000000","0.00000000"],["88651.59000000","0.00000000"],["88651.48000000","0.00000000"],["88651.47000000","0.00012000"],["88650.32000000","0.00006000"],["88650.27000000","0.03506000"],["88648.76000000","0.02937000"],["88648.69000000","0.00677000"],["88634.52000000","0.00000000"],["88633.66000000","0.00000000"],["88633.65000000","0.00000000"],["88633.64000000","0.00000000"],["88633.62000000","0.00000000"],["88633.60000000","0.00000000"],["88633.58000000","0.00000000"],["88633.47000000","0.05648000"],["88626.97000000","0.00000000"],["88626.48000000","0.40671000"],["88617.07000000","0.00000000"],["88612.85000000","0.40678000"],["88360.98000000","0.00000000"],["88000.00000000","10.12726000"],["79794.89000000","0.00252000"],["79794.00000000","0.00010000"],["70928.79000000","0.00028000"]],"a":[["88660.99000000","5.52189000"],["88670.20000000","0.01298000"],["88676.50000000","0.04200000"],["88677.55000000","0.00000000"],["88678.99000000","0.76214000"],["88680.21000000","0.00564000"],["88680.81000000","0.00000000"],["88681.74000000","0.00000000"],["88681.99000000","0.00000000"],["88700.42000000","0.01184000"],["88701.58000000","0.00000000"],["88738.68000000","0.00000000"],["88739.96000000","0.13675000"],["88743.57000000","0.10494000"],["88745.32000000","0.10494000"],["88759.35000000","0.00000000"],["88770.52000000","0.00000000"],["88960.99000000","0.00000000"],["89000.00000000","11.31810000"],["89179.71000000","0.21928000"],["89182.63000000","0.00075000"]]}
{"e":"depthUpdate","E":1767174247014,"s":"BTCUSDT","U":84208128421,"u":84208130609,"b":[["88660.98000000","0.00000000"],["88660.97000000","0.00000000"],["88660.96000000","0.00000000"],["88660.95000000","0.00000000"],["88660.45000000","0.00000000"],["88660.44000000","0.00000000"],["88657.92000000","0.00000000"],["88657.45000000","0.00000000"],["88657.44000000","0.00000000"],["88656.95000000","0.00000000"],["88656.52000000","0.00000000"],["88656.05000000","0.00000000"],["88655.70000000","0.00000000"],["88655.68000000","0.00000000"],["88655.12000000","0.00000000"],["88654.78000000","0.00000000"],["88654.77000000","0.00000000"],["88654.35000000","0.00000000"],["88654.09000000","0.00000000"],["88654.01000000","0.00000000"],["88654.00000000","0.00000000"],["88653.48000000","0.00000000"],["88653.45000000","0.00000000"],["88653.16000000","0.00000000"],["88653.15000000","0.00000000"],["88653.01000000","0.00000000"],["88652.01000000","0.00000000"],["88651.98000000","0.00000000"],["88651.97000000","0.00000000"],["88651.73000000","0.00000000"],["88651.66000000","0.00000000"],["88651.47000000","0.00000000"],["88651.37000000","0.00000000"],["88651.26000000","0.00000000"],["88651.24000000","0.00000000"],["88651.14000000","0.00000000"],["88651.01000000","0.00000000"],["88651.00000000","4.50193000"],["88650.99000000","0.00123000"],["88650.98000000","0.00039000"],["88650.97000000","0.00000000"],["88650.96000000","0.00000000"],["88650.91000000","0.00000000"],["88650.68000000","0.00000000"],["88650.50000000","0.00006000"],["88650.38000000","0.13766000"],["88650.37000000","0.00012000"],["88650.36000000","0.07555000"],["88650.35000000","0.00198000"],["88650.32000000","0.00012000"],["88650.28000000","0.00012000"],["88650.27000000","0.03518000"],["88650.17000000","0.00000000"],["88650.01000000","0.00012000"],["88650.00000000","0.01752000"],["88649.88000000","0.00000000"],["88649.78000000","0.00000000"],["88649.66000000","0.00000000"],["88649.44000000","0.00000000"],["88649.43000000","0.10518000"],["88649.38000000","0.03868000"],["88649.37000000","0.04218000"],["88649.28000000","0.00000000"],["88649.04000000","0.00250000"],["88648.78000000","0.00006000"],["88648.77000000","0.00000000"],["88648.76000000","0.02937000"],["88648.69000000","0.00006000"],["88648.63000000","0.00006000"],["88648.57000000","0.00062000"],["88648.56000000","0.00300000"],["88648.52000000","0.00000000"],["88648.40000000","0.00000000"],["88648.28000000","0.00000000"],["88648.18000000","0.00006000"],["88648.16000000","0.00000000"],["88648.00000000","0.00100000"],["88647.93000000","0.00000000"],["88647.87000000","0.00000000"],["88647.86000000","0.00006000"],["88647.71000000","0.00126000"],["88647.66000000","0.00000000"],["88647.55000000","0.00000000"],["88647.50000000","0.00000000"],["88647.46000000","0.00000000"],["88647.41000000","0.00000000"],["88647.37000000","0.00676000"],["88647.26000000","0.00006000"],["88647.15000000","0.00007000"],["88646.87000000","0.00006000"],["88646.82000000","0.00262000"],["88646.78000000","0.15163000"],["88646.77000000","0.04206000"],["88646.33000000","0.04206000"],["88646.00000000","0.00100000"],["88645.98000000","0.00006000"],["88645.92000000","0.12392000"],["88645.88000000","0.04206000"],["88645.74000000","0.00000000"],["88645.71000000","0.00000000"],["88645.62000000","0.00000000"],["88645.58000000","0.00000000"],["88645.56000000","0.00000000"],["88645.53000000","0.00000000"],["88645.48000000","0.00000000"],["88645.44000000","0.00000000"],["88645.34000000","0.00000000"],["88645.23000000","0.02006000"],["88645.03000000","0.00119000"],["88645.00000000","0.08406000"],["88644.94000000","0.04200000"],["88644.65000000","0.00056000"],["88644.60000000","0.00250000"],["88644.58000000","0.00000000"],["88644.51000000","0.00000000"],["88644.28000000","0.00500000"],["88643.71000000","0.00000000"],["88643.53000000","0.00000000"],["88643.48000000","0.00000000"],["88643.40000000","0.00000000"],["88643.38000000","0.00000000"],["88642.88000000","0.01006000"],["88642.45000000","0.00000000"],["88642.41000000","0.00000000"],["88642.38000000","0.00250000"],["88642.37000000","0.00000000"],["88642.36000000","0.00000000"],["88642.35000000","0.00006000"],["88641.83000000","0.00000000"],["88641.81000000","0.00000000"],["88641.59000000","0.00000000"],["88641.55000000","0.00000000"],["88641.54000000","0.00000000"],["88641.34000000","0.00000000"],["88641.33000000","0.00000000"],["88641.27000000","0.00000000"],["88641.26000000","0.00000000"],["88641.24000000","0.03385000"],["88641.19000000","0.00048000"],["88641.09000000","0.00000000"],["88640.50000000","0.00048000"],["88640.42000000","0.00188000"],["88640.16000000","0.00250000"],["88639.75000000","0.11608000"],["88639.62000000","0.00000000"],["88639.32000000","0.01108000"],["88638.12000000","0.07000000"],["88638.08000000","0.00000000"],["88637.72000000","0.00000000"],["88637.57000000","0.00000000"],["88637.41000000","0.02560000"],["88636.60000000","0.18046000"],["88636.00000000","0.00293000"],["88635.77000000","0.00564000"],["88635.71000000","0.00000000"],["88635.63000000","0.00000000"],["88635.00000000","0.17500000"],["88634.77000000","0.67674000"],["88634.76000000","0.90748000"],["88634.75000000","0.00000000"],["88634.58000000","0.00000000"],["88634.45000000","0.00006000"],["88634.18000000","0.00000000"],["88634.17000000","0.00000000"],["88633.73000000","1.86283000"],["88633.72000000","0.00000000"],["88633.51000000","0.00000000"],["88633.50000000","0.00564000"],["88633.48000000","0.00000000"],["88633.47000000","0.00000000"],["88632.88000000","0.00000000"],["88632.38000000","0.00300000"],["88632.37000000","0.00000000"],["88632.01000000","0.00000000"],["88631.31000000","0.21896000"],["88631.20000000","0.00000000"],["88631.19000000","0.67674000"],["88631.18000000","0.00000000"],["88631.17000000","0.00000000"],["88630.96000000","0.00006000"],["88630.72000000","0.00009000"],["88630.26000000","0.00000000"],["88629.15000000","0.00000000"],["88629.08000000","0.00000000"],["88629.07000000","0.00000000"],["88628.82000000","0.00000000"],["88628.73000000","0.05648000"],["88628.11000000","0.00000000"],["88628.02000000","0.05853000"],["88628.01000000","0.05646000"],["88628.00000000","0.00186000"],["88627.86000000","0.00000000"],["88627.85000000","0.00000000"],["88627.32000000","0.00000000"],["88626.75000000","0.00000000"],["88626.71000000","0.00000000"],["88626.51000000","0.00000000"],["88626.48000000","0.00000000"],["88626.17000000","0.00300000"],["88626.04000000","0.00000000"],["88625.95000000","0.00000000"],["88625.82000000","0.00000000"],["88625.56000000","0.02824000"],["88625.14000000","0.06325000"],["88624.27000000","0.00000000"],["88624.02000000","0.00000000"],["88622.60000000","0.00000000"],["88621.60000000","0.00000000"],["88621.54000000","0.04200000"],["88621.51000000","0.00000000"],["88621.18000000","0.04516000"],["88620.45000000","0.00192000"],["88620.05000000","0.00000000"],["88619.64000000","0.00120000"],["88618.97000000","0.00000000"],["88618.90000000","0.00012000"],["88616.54000000","0.00006000"],["88616.00000000","0.00186000"],["88615.56000000","0.00000000"],["88614.38000000","0.05639000"],["88613.66000000","0.00000000"],["88613.04000000","0.27658000"],["88612.32000000","0.00000000"],["88612.15000000","0.00006000"],["88611.95000000","0.40678000"],["88611.93000000","0.00000000"],["88611.11000000","0.00112000"],["88610.82000000","0.00000000"],["88610.35000000","0.80125000"],["88609.33000000","0.00000000"],["88608.65000000","0.00000000"],["88608.62000000","0.25262000"],["88608.61000000","0.00000000"],["88607.76000000","0.00006000"],["88607.29000000","0.00000000"],["88607.08000000","0.40680000"],["88607.04000000","0.00000000"],["88605.90000000","0.00000000"],["88604.46000000","0.00000000"],["88603.45000000","0.00000000"],["88602.85000000","0.00000000"],["88602.84000000","0.20317000"],["88602.28000000","0.00000000"],["88602.22000000","0.00000000"],["88602.05000000","0.00000000"],["88601.95000000","0.00000000"],["88601.71000000","0.00000000"],["88601.22000000","0.00000000"],["88601.10000000","0.00000000"],["88600.90000000","0.00013000"],["88600.68000000","0.00000000"],["88600.59000000","0.00000000"],["88599.95000000","0.00000000"],["88599.89000000","0.00000000"],["88599.23000000","0.00000000"],["88598.31000000","0.00000000"],["88597.79000000","0.00000000"],["88596.63000000","0.00000000"],["88596.52000000","0.00600000"],["88596.47000000","0.00013000"],["88596.14000000","0.00000000"],["88595.03000000","0.00000000"],["88594.58000000","0.00000000"],["88594.43000000","0.00000000"],["88593.87000000","0.00000000"],["88593.80000000","0.00000000"],["88593.63000000","0.00000000"],["88593.53000000","0.00000000"],["88593.29000000","0.00000000"],["88592.92000000","0.06300000"],["88592.80000000","0.00000000"],["88592.74000000","0.00000000"],["88592.27000000","0.00000000"],["88592.20000000","0.00000000"],["88591.97000000","0.00000000"],["88591.55000000","0.00000000"],["88591.25000000","0.00012000"],["88590.92000000","0.00000000"],["88590.56000000","0.20840000"],["88590.00000000","0.00180000"],["88589.96000000","0.02402000"],["88589.47000000","0.00000000"],["88588.21000000","0.00000000"],["88588.08000000","0.04360000"],["88587.74000000","0.00000000"],["88586.65000000","0.07830000"],["88586.14000000","0.00000000"],["88585.89000000","0.00200000"],["88584.56000000","0.00000000"],["88584.21000000","0.00000000"],["88583.85000000","0.00424000"],["88583.28000000","0.00436000"],["88581.11000000","0.00000000"],["88580.57000000","0.00000000"],["88580.40000000","0.00000000"],["88580.06000000","0.00000000"],["88579.39000000","0.00000000"],["88578.89000000","0.00000000"],["88578.41000000","0.00000000"],["88576.84000000","0.00000000"],["88576.28000000","0.03052000"],["88575.01000000","0.00000000"],["88573.52000000","0.00000000"],["88572.83000000","0.14237000"],["88572.46000000","0.00000000"],["88570.02000000","0.00281000"],["88569.69000000","0.03213000"],["88568.91000000","0.00000000"],["88567.02000000","0.00000000"],["88565.42000000","0.00000000"],["88562.02000000","0.00281000"],["88557.82000000","0.00000000"],["88557.30000000","0.00000000"],["88555.22000000","0.00000000"],["88555.21000000","0.00000000"],["88544.84000000","0.00281000"],["88532.21000000","0.00000000"],["88532.20000000","0.12237000"],["88530.07000000","0.00000000"],["88530.06000000","0.00000000"],["88523.53000000","0.09976000"],["88520.10000000","0.00000000"],["88509.97000000","0.00000000"],["88506.60000000","0.02370000"],["88503.53000000","0.00203000"],["88491.57000000","0.00000000"],["88483.81000000","0.00000000"],["88481.67000000","0.00112000"],["88480.31000000","0.00000000"],["88474.17000000","0.00000000"],["88473.53000000","0.00112000"],["88473.36000000","0.00000000"],["88473.09000000","0.00000000"],["88472.28000000","0.00000000"],["88472.02000000","0.00000000"],["88471.21000000","0.00000000"],["88468.87000000","0.00000000"],["88466.68000000","0.00000000"],["88466.67000000","0.00000000"],["88459.66000000","0.00589000"],["88456.60000000","0.00112000"],["88452.98000000","0.03198000"],["88451.72000000","0.03198000"],["88450.29000000","0.03198000"],["88449.28000000","0.03198000"],["88448.42000000","0.03198000"],["88447.27000000","0.03198000"],["88437.90000000","1.13218000"],["88405.14000000","0.00012000"],["88400.71000000","0.00012000"],["88313.48000000","0.00000000"],["88313.05000000","0.00000000"],["88312.64000000","0.00000000"],["88312.24000000","0.00000000"],["88312.23000000","0.00000000"],["88311.09000000","0.00000000"],["88310.10000000","0.00000000"],["79794.89000000","0.00000000"],["79794.00000000","0.00000000"],["79791.71000000","0.00000000"],["79785.90000000","0.00154000"],["79785.00000000","0.00534000"],["70928.79000000","0.00000000"],["70920.80000000","0.00028000"],["62057.10000000","0.00000000"],["44330.49000000","0.00025000"],["44292.43000000","0.00000000"],["33000.00000000","6.20342000"]],"a":[["88651.01000000","7.12410000"],["88651.14000000","0.00000000"],["88651.15000000","0.00000000"],["88651.25000000","0.00000000"],["88651.27000000","0.00000000"],["88651.49000000","0.00012000"],["88651.50000000","0.01113000"],["88651.51000000","0.00006000"],["88651.66000000","0.00006000"],["88651.67000000","0.00012000"],["88651.68000000","0.01140000"],["88651.74000000","0.00000000"],["88651.99000000","0.00000000"],["88652.64000000","0.00000000"],["88652.65000000","0.00000000"],["88653.02000000","0.00000000"],["88653.15000000","0.00000000"],["88653.16000000","0.00000000"],["88653.32000000","0.00012000"],["88653.33000000","0.09261000"],["88653.48000000","0.00000000"],["88653.49000000","0.00000000"],["88653.99000000","0.00012000"],["88654.00000000","0.04115000"],["88654.01000000","0.00000000"],["88654.10000000","0.00000000"],["88654.35000000","0.00000000"],["88654.36000000","0.00000000"],["88654.51000000","0.00006000"],["88654.76000000","0.00006000"],["88654.77000000","0.22006000"],["88654.78000000","0.14012000"],["88654.79000000","0.00000000"],["88655.13000000","0.00000000"],["88655.43000000","0.00658000"],["88655.67000000","0.00000000"],["88655.69000000","0.00000000"],["88655.70000000","0.00250000"],["88656.01000000","0.00000000"],["88656.05000000","0.00006000"],["88656.06000000","0.00000000"],["88656.29000000","0.00055000"],["88656.52000000","0.00000000"],["88656.53000000","0.11343000"],["88657.00000000","0.00000000"],["88657.22000000","0.00300000"],["88657.45000000","0.00000000"],["88657.46000000","0.47038000"],["88657.54000000","0.00000000"],["88657.68000000","0.11449000"],["88657.91000000","0.00000000"],["88657.92000000","0.00250000"],["88657.93000000","0.00000000"],["88657.96000000","0.00006000"],["88658.70000000","0.59352000"],["88658.71000000","0.67674000"],["88658.87000000","0.00007000"],["88659.10000000","0.00000000"],["88659.38000000","0.00006000"],["88659.88000000","0.27000000"],["88659.89000000","0.02000000"],["88660.14000000","0.00250000"],["88660.19000000","0.01500000"],["88660.35000000","0.00055000"],["88660.44000000","0.00006000"],["88660.45000000","0.00000000"],["88660.46000000","0.00000000"],["88660.52000000","0.13600000"],["88660.94000000","0.00000000"],["88660.95000000","0.00000000"],["88660.96000000","0.14000000"],["88660.97000000","0.00000000"],["88660.98000000","0.25331000"],["88660.99000000","0.60529000"],["88661.00000000","0.00155000"],["88661.15000000","0.00000000"],["88661.16000000","0.07645000"],["88661.46000000","0.00000000"],["88661.70000000","0.00000000"],["88661.71000000","0.00000000"],["88661.81000000","0.00000000"],["88661.82000000","0.00000000"],["88661.88000000","0.00000000"],["88662.00000000","0.01370000"],["88662.08000000","0.00012000"],["88662.27000000","0.00000000"],["88662.28000000","0.37794000"],["88662.29000000","0.67674000"],["88662.33000000","0.00000000"],["88662.76000000","0.00000000"],["88663.00000000","0.00000000"],["88663.67000000","0.00000000"],["88663.99000000","0.00006000"],["88664.07000000","0.40654000"],["88664.21000000","0.00000000"],["88664.22000000","0.00000000"],["88664.29000000","0.04509000"],["88664.30000000","0.00112000"],["88664.52000000","0.00564000"],["88664.53000000","0.04272000"],["88664.58000000","0.00000000"],["88664.68000000","0.05646000"],["88664.86000000","0.00000000"],["88664.87000000","0.03385000"],["88665.42000000","0.00000000"],["88665.43000000","0.00000000"],["88665.79000000","0.00000000"],["88666.00000000","0.00087000"],["88666.27000000","0.00000000"],["88666.50000000","0.00012000"],["88666.52000000","0.99710000"],["88666.53000000","1.86283000"],["88666.54000000","0.00000000"],["88666.67000000","0.00000000"],["88666.80000000","0.00250000"],["88666.88000000","0.01169000"],["88667.03000000","0.00000000"],["88667.16000000","0.00000000"],["88667.64000000","0.04620000"],["88667.85000000","0.00000000"],["88667.88000000","0.03383000"],["88668.27000000","0.40652000"],["88668.38000000","0.00000000"],["88669.01000000","0.00000000"],["88669.02000000","0.00000000"],["88669.99000000","0.00000000"],["88670.00000000","0.00000000"],["88670.20000000","0.00000000"],["88670.33000000","0.00000000"],["88670.96000000","0.00000000"],["88671.18000000","0.00000000"],["88671.19000000","0.00000000"],["88671.21000000","0.00000000"],["88671.24000000","0.00000000"],["88671.71000000","0.00000000"],["88671.85000000","0.00000000"],["88671.97000000","0.00000000"],["88672.08000000","0.04200000"],["88672.30000000","0.00000000"],["88672.45000000","0.00000000"],["88672.55000000","0.76220000"],["88673.22000000","0.00000000"],["88673.27000000","0.00000000"],["88673.40000000","0.02823000"],["88673.53000000","0.00347000"],["88673.71000000","0.00000000"],["88673.72000000","0.00000000"],["88674.03000000","0.00564000"],["88674.35000000","0.05370000"],["88674.96000000","0.00000000"],["88675.00000000","0.00000000"],["88675.10000000","0.00000000"],["88675.27000000","0.06253000"],["88675.43000000","0.00000000"],["88675.50000000","0.00000000"],["88675.54000000","0.00200000"],["88675.61000000","0.04200000"],["88675.84000000","0.00000000"],["88675.98000000","0.92812000"],["88676.37000000","0.00000000"],["88676.52000000","0.04200000"],["88676.93000000","0.00000000"],["88677.11000000","0.00000000"],["88677.12000000","0.00000000"],["88677.31000000","0.00000000"],["88677.33000000","0.00000000"],["88677.55000000","0.04516000"],["88677.56000000","0.00000000"],["88677.60000000","0.05640000"],["88677.99000000","0.00000000"],["88678.33000000","0.40648000"],["88678.43000000","0.00112000"],["88678.99000000","0.00000000"],["88679.00000000","0.00000000"],["88679.06000000","0.00000000"],["88679.23000000","0.00132000"],["88679.24000000","0.00000000"],["88679.61000000","0.00300000"],["88679.62000000","0.00000000"],["88680.21000000","0.00000000"],["88680.36000000","0.00000000"],["88680.85000000","0.00000000"],["88681.75000000","0.00000000"],["88682.03000000","0.00112000"],["88682.15000000","0.00000000"],["88683.55000000","0.00000000"],["88683.56000000","0.00000000"],["88684.65000000","0.04944000"],["88685.73000000","0.00000000"],["88685.82000000","0.00000000"],["88686.38000000","0.00000000"],["88686.86000000","0.00000000"],["88686.94000000","0.08442000"],["88687.34000000","0.05084000"],["88688.77000000","0.00000000"],["88689.92000000","0.00000000"],["88690.09000000","0.00000000"],["88691.99000000","0.00000000"],["88692.30000000","0.08549000"],["88692.88000000","0.00560000"],["88693.00000000","0.00000000"],["88694.10000000","0.01691000"],["88694.21000000","0.00000000"],["88694.25000000","0.04200000"],["88695.56000000","0.00000000"],["88695.82000000","0.00203000"],["88695.96000000","0.00000000"],["88696.07000000","0.00000000"],["88697.04000000","0.00615000"],["88697.78000000","0.04200000"],["88698.53000000","0.01726000"],["88698.69000000","0.04206000"],["88698.85000000","0.00428000"],["88699.10000000","0.00000000"],["88699.41000000","0.00424000"],["88699.95000000","0.00000000"],["88700.87000000","0.00000000"],["88701.07000000","0.00000000"],["88701.10000000","0.00000000"],["88701.46000000","0.08455000"],["88701.47000000","0.00000000"],["88702.57000000","0.00014000"],["88702.58000000","0.00000000"],["88704.09000000","0.00000000"],["88704.34000000","0.00000000"],["88706.63000000","0.02743000"],["88707.54000000","0.00000000"],["88709.34000000","0.00000000"],["88709.35000000","0.00000000"],["88711.91000000","0.00247000"],["88712.37000000","0.00000000"],["88712.67000000","0.00000000"],["88712.68000000","0.00000000"],["88715.17000000","0.49710000"],["88715.23000000","0.00281000"],["88717.31000000","0.00000000"],["88717.94000000","0.00000000"],["88719.00000000","0.00000000"],["88720.82000000","0.12380000"],["88721.67000000","0.00000000"],["88721.77000000","0.00000000"],["88721.78000000","0.00000000"],["88723.04000000","0.00282000"],["88723.55000000","0.01078000"],["88724.22000000","0.01698000"],["88724.30000000","0.00111000"],["88724.32000000","0.87555000"],["88724.51000000","1.12852000"],["88725.24000000","0.00000000"],["88726.04000000","0.00000000"],["88728.95000000","0.00000000"],["88733.13000000","0.00000000"],["88733.18000000","0.00000000"],["88736.09000000","0.04360000"],["88736.29000000","0.00000000"],["88737.23000000","0.09210000"],["88738.36000000","0.02368000"],["88738.53000000","0.00000000"],["88739.26000000","0.07496000"],["88739.30000000","0.00000000"],["88739.54000000","0.00000000"],["88747.43000000","0.00000000"],["88748.39000000","0.00000000"],["88754.89000000","0.07496000"],["88755.84000000","0.06000000"],["88756.93000000","0.00000000"],["88759.75000000","0.00000000"],["88761.54000000","0.00000000"],["88764.66000000","0.00000000"],["88767.80000000","0.00000000"],["88769.60000000","0.00000000"],["88770.56000000","0.00000000"],["88777.06000000","0.00000000"],["88784.28000000","0.00000000"],["88798.62000000","0.00000000"],["88799.99000000","0.00093000"],["88801.39000000","0.00000000"],["88809.99000000","0.00000000"],["88810.71000000","0.00112000"],["88812.56000000","0.00112000"],["88814.12000000","0.00000000"],["88820.40000000","0.04611000"],["88822.42000000","0.00000000"],["88825.53000000","0.00000000"],["88843.02000000","0.00000000"],["88868.31000000","0.00000000"],["88883.63000000","0.00000000"],["88887.41000000","0.00000000"],["88917.38000000","0.00000000"],["88920.12000000","0.00000000"],["89168.03000000","0.21928000"],["89179.71000000","0.00000000"],["89529.80000000","0.00400000"],["89541.34000000","0.00000000"]]}
{"e":"depthUpdate","E":1767174248014,"s":"BTCUSDT","U":84208130610,"u":84208130884,"b":[["88651.00000000","4.44641000"],["88650.99000000","0.00117000"],["88650.98000000","0.00033000"],["88650.39000000","0.00012000"],["88650.38000000","0.08840000"],["88650.37000000","0.00000000"],["88650.36000000","0.07555000"],["88650.00000000","0.01752000"],["88649.92000000","0.00000000"],["88648.76000000","0.02937000"],["88648.72000000","0.00000000"],["88647.37000000","0.00676000"],["88647.19000000","0.00000000"],["88647.07000000","0.00000000"],["88645.00000000","0.13640000"],["88644.21000000","0.00000000"],["88643.90000000","0.13440000"],["88643.32000000","0.37275000"],["88642.94000000","0.00000000"],["88641.24000000","0.00000000"],["88641.13000000","0.00000000"],["88641.12000000","0.00000000"],["88641.11000000","0.03385000"],["88640.59000000","0.04200000"],["88639.75000000","0.17277000"],["88639.68000000","0.04200000"],["88636.60000000","0.18046000"],["88635.00000000","0.00000000"],["88629.76000000","0.05648000"],["88629.75000000","0.00000000"],["88629.74000000","0.00011000"],["88628.73000000","0.00000000"],["88628.71000000","0.00000000"],["88624.63000000","0.35631000"],["88623.44000000","0.78531000"],["88621.99000000","0.00000000"],["88621.51000000","0.40674000"],["88614.38000000","0.00000000"],["88611.95000000","0.00000000"],["88610.35000000","0.00000000"],["88608.42000000","0.08398000"],["88607.80000000","0.40680000"],["88607.08000000","0.00000000"],["88597.14000000","0.04200000"],["88596.52000000","0.00000000"],["88596.48000000","0.00600000"],["88592.91000000","0.00000000"],["88590.30000000","0.03052000"],["88588.08000000","0.00000000"],["88584.03000000","0.00000000"],["88578.61000000","0.00000000"],["88576.28000000","0.00000000"],["88575.70000000","0.04200000"],["88571.29000000","0.03213000"],["88569.69000000","0.00000000"],["88565.42000000","0.00000000"],["88544.85000000","0.00281000"],["88544.84000000","0.00000000"],["88543.72000000","0.00000000"],["88532.21000000","0.03768000"],["88501.77000000","0.00006000"],["88456.61000000","0.00112000"],["88456.60000000","0.00000000"],["88365.88000000","0.01767000"],["86770.91000000","0.00000000"],["81558.93000000","0.00000000"],["79785.90000000","0.00252000"],["79785.00000000","0.00534000"],["70921.00000000","0.00000000"],["70920.80000000","0.00028000"]],"a":[["88651.01000000","7.79626000"],["88652.16000000","0.00006000"],["88653.92000000","0.00006000"],["88654.77000000","0.33169000"],["88655.43000000","0.14658000"],["88655.70000000","0.05562000"],["88656.29000000","0.00000000"],["88656.53000000","0.25343000"],["88657.00000000","0.17672000"],["88657.22000000","0.00300000"],["88657.46000000","0.42923000"],["88657.68000000","0.11280000"],["88660.35000000","0.00000000"],["88660.96000000","0.00000000"],["88660.98000000","0.11331000"],["88660.99000000","0.60168000"],["88664.07000000","0.00000000"],["88664.34000000","0.00000000"],["88666.00000000","0.17587000"],["88666.72000000","0.07140000"],["88666.77000000","0.05250000"],["88667.61000000","0.04200000"],["88667.65000000","0.03500000"],["88670.27000000","0.04200000"],["88670.70000000","0.04200000"],["88672.05000000","0.05460000"],["88675.98000000","0.63008000"],["88676.46000000","0.00000000"],["88677.27000000","0.00000000"],["88677.35000000","0.00000000"],["88677.60000000","0.00000000"],["88678.53000000","0.00000000"],["88678.69000000","0.42147000"],["88679.90000000","0.60885000"],["88679.94000000","0.00000000"],["88681.71000000","0.00000000"],["88687.34000000","0.00000000"],["88688.88000000","0.07140000"],["88690.73000000","0.00000000"],["88692.87000000","0.04200000"],["88694.36000000","0.00000000"],["88697.19000000","0.05084000"],["88702.91000000","0.00169000"],["88706.54000000","0.00169000"],["88719.88000000","0.02859000"],["88724.00000000","0.17689000"],["88738.37000000","0.08995000"],["88743.00000000","0.00000000"],["88744.00000000","0.00180000"],["88747.00000000","0.00000000"],["88761.07000000","0.02143000"],["88769.16000000","0.00000000"],["88772.30000000","0.00000000"],["89168.03000000","0.00000000"],["89176.79000000","0.21928000"]]}
{"e":"depthUpdate","E":1767174249015,"s":"BTCUSDT","U":84208130885,"u":84208131008,"b":[["88651.00000000","4.45773000"],["88646.78000000","0.15163000"],["88646.33000000","0.04206000"],["88646.12000000","0.00000000"],["88645.88000000","0.04212000"],["88645.61000000","0.05208000"],["88645.18000000","0.00000000"],["88645.03000000","0.00119000"],["88645.00000000","0.08400000"],["88643.90000000","0.14748000"],["88643.32000000","0.00000000"],["88643.12000000","0.37275000"],["88640.37000000","0.00180000"],["88636.40000000","0.05647000"],["88635.00000000","0.00000000"],["88629.79000000","0.05648000"],["88629.78000000","0.00000000"],["88629.77000000","0.00000000"],["88629.76000000","0.00000000"],["88624.63000000","0.54517000"],["88588.05000000","0.04360000"],["88580.00000000","0.16449000"],["88523.54000000","0.03038000"],["88298.75000000","0.03198000"],["88297.23000000","0.03198000"],["88295.95000000","0.03198000"],["88295.04000000","0.03198000"],["88294.17000000","0.03198000"],["88293.33000000","0.03198000"],["88292.66000000","0.03198000"],["88291.88000000","0.03198000"],["88290.80000000","0.03198000"],["79785.90000000","0.00263000"],["79785.00000000","0.00534000"],["70920.80000000","0.00028000"],["60000.00000000","227.86147000"]],"a":[["88651.01000000","6.91558000"],["88651.37000000","0.00012000"],["88651.38000000","0.01140000"],["88651.50000000","0.01113000"],["88651.67000000","0.00000000"],["88651.68000000","0.00000000"],["88657.21000000","0.00045000"],["88671.62000000","0.00000000"],["88672.55000000","0.00000000"],["88674.34000000","0.76218000"],["88690.34000000","0.00169000"],["88690.90000000","0.00112000"],["88694.01000000","0.00000000"],["88696.28000000","0.03413000"],["88702.91000000","0.00000000"],["88706.54000000","0.00000000"],["88727.71000000","0.07496000"],["88743.99000000","0.03500000"]]}
{"e":"depthUpdate","E":1767174250014,"s":"BTCUSDT","U":84208131009,"u":84208131156,"b":[["88651.00000000","4.46367000"],["88650.99000000","0.00123000"],["88648.38000000","0.05213000"],["88648.00000000","0.00106000"],["88647.88000000","0.00000000"],["88646.82000000","0.00262000"],["88646.81000000","0.00000000"],["88645.88000000","0.04200000"],["88645.61000000","0.00000000"],["88645.28000000","0.00000000"],["88645.23000000","0.00006000"],["88645.09000000","0.37274000"],["88645.03000000","0.00113000"],["88645.00000000","0.08400000"],["88644.81000000","0.00000000"],["88643.90000000","0.02653000"],["88643.12000000","0.00000000"],["88642.96000000","0.00000000"],["88637.92000000","0.02000000"],["88635.00000000","0.00000000"],["88633.62000000","0.05648000"],["88633.61000000","0.00959000"],["88633.60000000","0.00000000"],["88629.79000000","0.00000000"],["88608.62000000","0.37586000"],["88594.15000000","0.01767000"],["88588.05000000","0.00000000"],["88588.04000000","0.04360000"],["88459.20000000","0.00000000"],["86411.43000000","0.00000000"],["80000.00000000","284.97387000"],["79785.90000000","0.00252000"],["79785.00000000","0.00534000"],["70921.00000000","0.00000000"],["70920.80000000","0.00028000"],["31914.36000000","0.00019000"]],"a":[["88651.01000000","7.73212000"],["88651.02000000","0.00012000"],["88656.53000000","0.25343000"],["88657.00000000","0.17675000"],["88657.21000000","0.00045000"],["88683.82000000","0.00169000"],["88690.34000000","0.00000000"],["88784.28000000","0.01767000"],["88845.00000000","0.00000000"]]}
{"e":"depthUpdate","E":1767174251014,"s":"BTCUSDT","U":84208131157,"u":84208131290,"b":[["88651.00000000","4.46439000"],["88650.99000000","0.00123000"],["88648.86000000","0.05254000"],["88648.56000000","0.00300000"],["88648.38000000","0.00000000"],["88648.00000000","0.00100000"],["88645.26000000","0.37274000"],["88645.09000000","0.00000000"],["88645.03000000","0.00119000"],["88643.90000000","0.02653000"],["88643.09000000","0.00000000"],["88636.40000000","0.00000000"],["88633.86000000","0.05647000"],["88633.62000000","0.00000000"],["88632.27000000","0.05648000"],["88632.26000000","0.00000000"],["88632.25000000","0.00000000"],["88632.24000000","0.00000000"],["88632.23000000","0.00000000"],["88632.22000000","0.00000000"],["88455.04000000","5.12352000"],["87151.00000000","0.00000000"],["87000.00000000","70.43704000"],["86411.43000000","0.00000000"],["79785.90000000","0.00238000"],["79785.00000000","0.00554000"],["70921.00000000","0.00000000"],["70920.80000000","0.00028000"],["31914.36000000","0.00038000"]],"a":[["88651.01000000","7.98128000"],["88651.02000000","0.00018000"],["88651.37000000","0.00000000"],["88651.38000000","0.00012000"],["88651.39000000","0.01140000"],["88657.46000000","0.28923000"],["88664.68000000","0.00000000"],["88665.97000000","0.05647000"],["88679.02000000","0.20318000"],["88680.00000000","0.03059000"],["88684.91000000","0.60450000"],["88686.66000000","0.00000000"],["88839.15000000","4.96044000"],["89173.87000000","0.21928000"],["89176.79000000","0.00000000"]]}
{"e":"depthUpdate","E":1767174252014,"s":"BTCUSDT","U":84208131291,"u":84208131381,"b":[["88651.00000000","4.47002000"],["88649.37000000","0.04218000"],["88649.04000000","0.00256000"],["88648.69000000","0.00000000"],["88648.57000000","0.00006000"],["88645.03000000","0.00119000"],["88635.05000000","0.00113000"],["88633.86000000","0.00000000"],["88632.37000000","0.05648000"],["88632.36000000","0.00000000"],["88632.35000000","0.00000000"],["88632.34000000","0.00000000"],["88632.32000000","0.00000000"],["88632.31000000","0.00000000"],["88632.30000000","0.00000000"],["88632.29000000","0.03500000"],["88632.27000000","0.00000000"],["88629.52000000","0.00000000"],["88597.87000000","0.00000000"],["88568.12000000","0.00000000"],["87985.01000000","0.00985000"],["79785.90000000","0.00252000"],["79785.00000000","0.00534000"],["70920.80000000","0.00028000"],["33000.00000000","6.20342000"],["31914.36000000","0.00095000"]],"a":[["88651.01000000","7.97828000"],["88660.99000000","0.59041000"],["88663.42000000","0.00056000"],["88665.97000000","0.00000000"],["88676.47000000","0.79602000"],["88676.94000000","0.00000000"],["88683.82000000","0.00000000"],["88700.00000000","1.25316000"],["88710.00000000","0.00230000"],["88719.88000000","0.02142000"],["88720.98000000","0.03875000"]]}
{"e":"depthUpdate","E":1767174253014,"s":"BTCUSDT","U":84208131382,"u":84208131529,"b":[["88651.00000000","4.47183000"],["88650.99000000","0.00129000"],["88650.38000000","0.12427000"],["88650.37000000","0.00006000"],["88650.27000000","0.03524000"],["88650.12000000","0.05142000"],["88650.01000000","0.00006000"],["88649.37000000","0.04206000"],["88649.33000000","0.00000000"],["88649.04000000","0.00256000"],["88648.94000000","0.01122000"],["88648.86000000","0.00000000"],["88645.26000000","0.00000000"],["88645.16000000","0.37274000"],["88645.03000000","0.00113000"],["88643.90000000","0.14748000"],["88643.25000000","0.00000000"],["88639.32000000","0.00000000"],["88636.54000000","0.05647000"],["88635.00000000","0.17500000"],["88632.88000000","0.05648000"],["88632.87000000","0.00000000"],["88632.38000000","0.00300000"],["88632.37000000","0.00000000"],["88616.12000000","0.04200000"],["88593.06000000","0.24600000"],["88592.92000000","0.00000000"],["88578.42000000","0.17051000"],["88553.53000000","0.00000000"],["81558.93000000","0.00013000"],["79785.90000000","0.00238000"],["79785.00000000","0.00534000"],["70921.00000000","0.00000000"],["70920.80000000","0.00028000"],["42000.00000000","16.04102000"]],"a":[["88651.01000000","6.38821000"],["88651.39000000","0.01140000"],["88652.16000000","0.00182000"],["88657.00000000","0.00000000"],["88660.99000000","0.53405000"],["88666.00000000","0.00087000"],["88680.00000000","0.02890000"],["88685.79000000","0.23832000"],["88700.00000000","1.11316000"],["88724.00000000","0.00189000"],["88751.44000000","0.06000000"],["88759.09000000","0.00000000"],["89173.87000000","0.00000000"],["89176.79000000","0.21928000"]]}
{"e":"depthUpdate","E":1767174254014,"s":"BTCUSDT","U":84208131530,"u":84208131645,"b":[["88651.00000000","4.63322000"],["88648.94000000","0.00000000"],["88647.75000000","0.01144000"],["88645.88000000","0.04206000"],["88645.23000000","0.00000000"],["88643.90000000","0.02653000"],["88635.00000000","0.00000000"],["88634.84000000","0.00000000"],["88634.83000000","0.00000000"],["88634.82000000","0.00000000"],["88633.86000000","0.00000000"],["88632.88000000","0.00000000"],["88597.04000000","0.06300000"],["88596.48000000","0.00000000"],["88596.38000000","0.00600000"],["88588.04000000","0.00000000"],["88587.94000000","0.04360000"],["88582.69000000","0.00000000"],["88575.29000000","0.00147000"],["81558.93000000","0.00000000"],["79785.90000000","0.00252000"],["79785.00000000","0.00534000"],["70920.80000000","0.00028000"]],"a":[["88651.01000000","7.21376000"],["88651.39000000","0.01140000"],["88655.70000000","0.05312000"],["88656.53000000","0.25343000"],["88657.00000000","0.17500000"],["88662.51000000","0.05647000"],["88664.58000000","0.00250000"],["88666.00000000","0.17587000"],["88672.58000000","0.00169000"],["88674.34000000","0.00000000"],["88675.96000000","1.05662000"],["88675.97000000","0.76217000"],["88675.98000000","0.00000000"],["88687.00000000","0.00000000"],["88710.00000000","0.14230000"],["88724.00000000","0.17689000"],["88728.14000000","0.00147000"]]}
{"e":"depthUpdate","E":1767174255014,"s":"BTCUSDT","U":84208131646,"u":84208132202,"b":[["88651.00000000","6.01993000"],["88650.99000000","0.00033000"],["88650.39000000","0.00012000"],["88650.37000000","0.00006000"],["88650.32000000","0.00012000"],["88650.28000000","0.00012000"],["88650.27000000","0.03518000"],["88650.12000000","0.00012000"],["88650.01000000","0.00006000"],["88649.37000000","0.04218000"],["88649.04000000","0.00250000"],["88648.85000000","0.00000000"],["88648.00000000","0.00106000"],["88647.75000000","0.00000000"],["88647.72000000","0.01107000"],["88646.84000000","0.00000000"],["88646.78000000","0.65050000"],["88645.68000000","1.86283000"],["88645.16000000","0.00000000"],["88644.38000000","0.00000000"],["88644.29000000","0.00564000"],["88644.21000000","0.03934000"],["88644.20000000","0.00000000"],["88643.90000000","0.00000000"],["88641.81000000","0.00055000"],["88641.19000000","0.00000000"],["88640.99000000","0.00000000"],["88640.50000000","0.00000000"],["88640.42000000","0.00000000"],["88639.85000000","0.67674000"],["88639.75000000","0.66030000"],["88639.20000000","1.86283000"],["88637.92000000","0.00000000"],["88636.60000000","0.00000000"],["88636.58000000","0.04272000"],["88636.54000000","0.00000000"],["88636.01000000","0.00113000"],["88636.00000000","0.00180000"],["88635.77000000","0.00000000"],["88635.00000000","0.17500000"],["88634.82000000","0.00000000"],["88634.80000000","0.00000000"],["88634.79000000","0.00000000"],["88634.78000000","0.00000000"],["88634.77000000","0.67674000"],["88634.75000000","0.00000000"],["88634.74000000","0.00000000"],["88634.40000000","0.04516000"],["88634.13000000","0.00000000"],["88633.24000000","0.00346000"],["88631.31000000","0.03850000"],["88630.85000000","0.00000000"],["88630.39000000","0.00000000"],["88628.46000000","0.18046000"],["88628.01000000","0.00000000"],["88623.29000000","0.00000000"],["88621.51000000","0.00000000"],["88621.18000000","0.00000000"],["88621.17000000","0.00000000"],["88619.44000000","0.00000000"],["88617.57000000","0.00000000"],["88615.86000000","0.44876000"],["88612.85000000","0.00000000"],["88611.46000000","0.24598000"],["88608.62000000","0.25262000"],["88607.80000000","0.00000000"],["88606.73000000","0.03213000"],["88606.28000000","0.03052000"],["88606.14000000","0.00000000"],["88602.65000000","0.00000000"],["88598.29000000","0.18046000"],["88596.38000000","0.00000000"],["88596.32000000","0.00000000"],["88596.30000000","0.00000000"],["88595.59000000","0.18002000"],["88593.06000000","0.00000000"],["88590.30000000","0.00000000"],["88590.09000000","0.00000000"],["88587.94000000","0.00000000"],["88587.88000000","0.00000000"],["88587.87000000","0.00000000"],["88587.82000000","0.00000000"],["88587.80000000","0.00000000"],["88571.29000000","0.00000000"],["88563.80000000","0.12237000"],["88532.21000000","0.00000000"],["88532.20000000","0.00000000"],["79785.90000000","0.00238000"],["79785.00000000","0.00534000"],["70920.80000000","0.00028000"],["42000.00000000","16.04002000"]],"a":[["88651.01000000","0.96681000"],["88651.02000000","0.00006000"],["88651.38000000","0.00000000"],["88651.39000000","0.00012000"],["88651.49000000","0.00000000"],["88651.50000000","0.00000000"],["88651.52000000","0.00012000"],["88651.53000000","0.37284000"],["88652.16000000","0.00097000"],["88653.32000000","0.00000000"],["88653.33000000","0.00000000"],["88654.00000000","0.04115000"],["88654.76000000","0.00000000"],["88654.77000000","0.00000000"],["88654.78000000","0.00000000"],["88655.33000000","0.06185000"],["88655.43000000","0.00658000"],["88655.70000000","0.00000000"],["88656.53000000","0.00000000"],["88657.00000000","0.00000000"],["88657.45000000","0.00000000"],["88657.46000000","0.00012000"],["88657.67000000","0.00012000"],["88657.68000000","0.11292000"],["88657.92000000","0.00000000"],["88657.95000000","0.01000000"],["88658.20000000","0.01128000"],["88658.70000000","0.00000000"],["88658.71000000","0.00000000"],["88658.84000000","0.00000000"],["88659.58000000","0.00000000"],["88659.69000000","0.05125000"],["88659.88000000","0.27000000"],["88659.89000000","0.00000000"],["88660.14000000","0.00000000"],["88660.19000000","0.00012000"],["88660.51000000","0.00012000"],["88660.52000000","0.13612000"],["88660.89000000","0.00000000"],["88660.98000000","0.00006000"],["88660.99000000","0.49412000"],["88661.39000000","0.01500000"],["88661.55000000","0.14000000"],["88662.07000000","0.01128000"],["88662.28000000","0.00000000"],["88662.29000000","0.00000000"],["88662.36000000","0.00000000"],["88662.51000000","0.00000000"],["88664.29000000","0.00000000"],["88664.52000000","0.00000000"],["88664.53000000","0.00000000"],["88664.58000000","0.00000000"],["88664.69000000","0.02000000"],["88664.70000000","0.00000000"],["88664.87000000","0.00000000"],["88664.95000000","0.00000000"],["88665.40000000","0.00000000"],["88666.00000000","0.00000000"],["88666.01000000","0.00113000"],["88666.21000000","0.00000000"],["88666.52000000","0.00000000"],["88666.53000000","0.00000000"],["88666.55000000","0.00000000"],["88666.76000000","0.00000000"],["88667.04000000","0.00000000"],["88667.51000000","0.00000000"],["88667.52000000","0.00000000"],["88668.27000000","0.00000000"],["88669.02000000","0.00250000"],["88670.26000000","0.00000000"],["88670.44000000","0.00000000"],["88670.94000000","0.00000000"],["88670.97000000","0.00000000"],["88671.24000000","0.93116000"],["88672.56000000","0.00000000"],["88672.96000000","0.00000000"],["88673.40000000","0.00000000"],["88673.53000000","0.00000000"],["88673.54000000","0.00000000"],["88674.03000000","0.00000000"],["88674.24000000","0.00564000"],["88674.35000000","0.00000000"],["88674.51000000","0.00000000"],["88674.93000000","0.67674000"],["88674.94000000","0.00000000"],["88675.08000000","0.00000000"],["88675.11000000","0.00000000"],["88675.68000000","0.00250000"],["88675.96000000","0.00000000"],["88675.97000000","0.00000000"],["88676.42000000","0.43647000"],["88676.47000000","0.00169000"],["88677.54000000","0.00000000"],["88677.55000000","0.00000000"],["88677.90000000","0.00250000"],["88678.33000000","0.00000000"],["88678.69000000","0.01500000"],["88679.02000000","0.00000000"],["88679.37000000","0.67674000"],["88679.38000000","0.00007000"],["88679.90000000","0.00000000"],["88679.91000000","0.00000000"],["88681.58000000","0.00564000"],["88682.15000000","0.02823000"],["88683.28000000","0.33205000"],["88683.29000000","0.67674000"],["88683.95000000","0.00009000"],["88683.96000000","0.40645000"],["88684.65000000","0.00000000"],["88684.90000000","0.00000000"],["88685.37000000","0.00000000"],["88685.79000000","0.00000000"],["88686.86000000","0.67674000"],["88687.79000000","1.86283000"],["88687.80000000","0.00000000"],["88688.84000000","0.76206000"],["88689.67000000","0.40642000"],["88692.88000000","0.00000000"],["88693.92000000","0.89943000"],["88693.93000000","1.86283000"],["88693.97000000","0.00000000"],["88693.98000000","0.54289000"],["88695.13000000","0.18054000"],["88697.19000000","0.00000000"],["88698.46000000","0.00000000"],["88701.33000000","0.00000000"],["88702.64000000","0.23830000"],["88706.06000000","0.18046000"],["88710.00000000","0.00230000"],["88710.80000000","0.18046000"],["88711.47000000","0.00000000"],["88711.91000000","0.00247000"],["88713.00000000","0.04944000"],["88721.86000000","0.05084000"],["88724.00000000","0.00189000"],["88724.43000000","0.04800000"],["88728.17000000","0.00000000"],["88736.09000000","0.00000000"],["88744.71000000","0.00000000"],["88773.12000000","1.86283000"],["88783.76000000","1.86283000"],["88785.93000000","0.00000000"],["88799.99000000","0.00093000"],["88995.08000000","0.00000000"],["89082.71000000","0.34924000"],["89176.79000000","0.00000000"],["89179.71000000","0.00000000"]]}
{"e":"depthUpdate","E":1767174256014,"s":"BTCUSDT","U":84208132203,"u":84208132937,"b":[["88651.00000000","5.47322000"],["88650.38000000","0.11085000"],["88650.37000000","0.00012000"],["88650.27000000","0.03524000"],["88650.19000000","0.00006000"],["88650.18000000","0.05080000"],["88650.12000000","0.00000000"],["88649.44000000","0.00000000"],["88649.43000000","0.10518000"],["88648.88000000","0.00000000"],["88648.76000000","0.02937000"],["88648.56000000","0.00306000"],["88648.52000000","0.01400000"],["88648.28000000","0.04000000"],["88648.00000000","0.00100000"],["88647.72000000","0.00000000"],["88647.71000000","0.01237000"],["88647.53000000","0.00055000"],["88647.37000000","0.00682000"],["88647.24000000","0.02000000"],["88646.82000000","0.00262000"],["88646.78000000","0.15163000"],["88645.98000000","0.00000000"],["88645.92000000","0.12386000"],["88645.88000000","0.04200000"],["88645.68000000","0.00000000"],["88645.58000000","0.00110000"],["88644.92000000","0.00055000"],["88644.76000000","0.00110000"],["88644.29000000","0.00000000"],["88644.23000000","0.00055000"],["88644.21000000","0.29473000"],["88644.05000000","0.37275000"],["88643.14000000","0.00000000"],["88642.04000000","0.18046000"],["88641.78000000","0.02560000"],["88641.64000000","0.00110000"],["88641.51000000","0.00055000"],["88641.12000000","0.00564000"],["88641.10000000","0.00000000"],["88640.96000000","0.00000000"],["88640.93000000","0.00000000"],["88640.53000000","0.18046000"],["88640.00000000","0.19942000"],["88639.96000000","0.00000000"],["88639.86000000","0.67674000"],["88639.85000000","0.00000000"],["88639.65000000","0.00000000"],["88637.41000000","0.00000000"],["88637.06000000","0.05648000"],["88635.00000000","0.00000000"],["88634.40000000","0.00000000"],["88633.24000000","0.00000000"],["88632.78000000","0.04516000"],["88632.77000000","0.00000000"],["88630.96000000","0.00006000"],["88629.51000000","0.77951000"],["88629.31000000","0.06743000"],["88628.77000000","0.00346000"],["88628.46000000","0.00000000"],["88628.44000000","0.00000000"],["88628.02000000","0.00000000"],["88627.98000000","0.00000000"],["88624.63000000","0.35631000"],["88623.44000000","0.00000000"],["88610.98000000","0.40679000"],["88606.73000000","0.00000000"],["88606.28000000","0.00000000"],["88604.38000000","0.40682000"],["88602.49000000","0.00550000"],["88602.33000000","0.40682000"],["88598.07000000","0.00600000"],["88595.84000000","0.03052000"],["88593.12000000","0.00000000"],["88590.57000000","0.04360000"],["88586.65000000","0.00433000"],["88586.08000000","0.00600000"],["88585.89000000","0.00000000"],["88585.47000000","0.00000000"],["88582.70000000","0.02998000"],["88582.54000000","0.00000000"],["88580.00000000","0.02449000"],["88579.79000000","0.00000000"],["88579.43000000","0.13293000"],["88577.68000000","0.00000000"],["88574.45000000","0.08995000"],["88573.51000000","0.16693000"],["88572.45000000","0.17692000"],["88571.45000000","0.25188000"],["88570.01000000","0.09196000"],["88569.31000000","0.03213000"],["88568.90000000","0.83328000"],["88568.15000000","0.19259000"],["88568.01000000","0.00000000"],["88567.11000000","0.00000000"],["88566.18000000","0.78478000"],["88564.37000000","1.59213000"],["88564.01000000","0.26687000"],["88563.73000000","0.07496000"],["88562.70000000","0.10494000"],["88560.18000000","1.10544000"],["88559.18000000","0.47580000"],["88558.70000000","0.10195000"],["88557.93000000","0.26887000"],["88557.34000000","0.26087000"],["88555.90000000","0.17991000"],["88555.08000000","0.09296000"],["88553.14000000","0.07497000"],["88552.39000000","0.09296000"],["88551.10000000","0.07497000"],["88549.95000000","0.09307000"],["88547.41000000","0.07497000"],["86770.91000000","0.00000000"],["79785.90000000","0.00252000"],["79785.00000000","0.00534000"],["76600.00000000","1.31064000"],["70920.80000000","0.00028000"]],"a":[["88651.01000000","5.40110000"],["88651.02000000","0.00012000"],["88651.06000000","0.00012000"],["88651.07000000","0.01144000"],["88651.39000000","0.00000000"],["88651.50000000","0.00012000"],["88651.51000000","0.14797000"],["88651.52000000","0.00000000"],["88651.53000000","0.00000000"],["88651.60000000","0.00012000"],["88651.61000000","0.37284000"],["88652.02000000","0.00000000"],["88652.03000000","0.01668000"],["88652.16000000","0.00006000"],["88652.63000000","0.00012000"],["88652.64000000","0.02572000"],["88652.99000000","0.00012000"],["88653.00000000","0.05660000"],["88653.09000000","0.00112000"],["88653.31000000","0.00000000"],["88653.83000000","0.00000000"],["88653.84000000","0.00000000"],["88653.85000000","0.00000000"],["88653.92000000","0.00000000"],["88653.99000000","0.00000000"],["88654.00000000","0.00000000"],["88655.32000000","0.00000000"],["88655.33000000","0.06197000"],["88655.43000000","0.00658000"],["88657.04000000","0.00000000"],["88657.05000000","0.00000000"],["88657.46000000","0.00000000"],["88657.67000000","0.00000000"],["88657.68000000","0.11292000"],["88657.95000000","0.00000000"],["88658.19000000","0.00000000"],["88658.20000000","0.01128000"],["88659.68000000","0.00000000"],["88659.69000000","0.00000000"],["88659.87000000","0.34249000"],["88659.88000000","0.27000000"],["88660.14000000","0.00250000"],["88660.19000000","0.00000000"],["88660.51000000","0.00000000"],["88660.52000000","0.13600000"],["88660.98000000","0.00000000"],["88660.99000000","0.46962000"],["88661.29000000","0.00000000"],["88661.39000000","0.00000000"],["88661.42000000","0.00000000"],["88661.44000000","0.00000000"],["88661.55000000","0.00000000"],["88661.75000000","0.00000000"],["88662.07000000","0.00000000"],["88662.36000000","0.00250000"],["88662.44000000","0.09002000"],["88662.45000000","0.07000000"],["88663.19000000","0.00000000"],["88663.33000000","0.00000000"],["88663.45000000","0.08000000"],["88663.88000000","0.00007000"],["88664.58000000","0.00250000"],["88664.68000000","0.00000000"],["88665.00000000","0.00268000"],["88665.49000000","0.00000000"],["88665.59000000","0.01500000"],["88666.21000000","0.00009000"],["88666.47000000","0.00347000"],["88666.76000000","0.34937000"],["88667.55000000","0.67686000"],["88667.87000000","0.00000000"],["88667.88000000","0.03383000"],["88667.89000000","0.03385000"],["88668.66000000","0.18046000"],["88671.22000000","0.75805000"],["88671.23000000","0.67674000"],["88671.24000000","0.00000000"],["88671.60000000","0.18046000"],["88672.58000000","0.00000000"],["88672.84000000","0.76220000"],["88673.46000000","0.00000000"],["88674.00000000","0.00000000"],["88674.72000000","0.04272000"],["88675.08000000","0.00009000"],["88675.27000000","0.00000000"],["88675.68000000","0.00000000"],["88676.15000000","0.00000000"],["88676.35000000","0.00000000"],["88676.41000000","1.86283000"],["88676.42000000","0.51342000"],["88676.45000000","0.06131000"],["88676.47000000","0.00000000"],["88676.48000000","0.00000000"],["88677.12000000","0.79708000"],["88677.90000000","0.00000000"],["88678.22000000","0.40648000"],["88680.65000000","0.06558000"],["88682.13000000","0.00000000"],["88682.14000000","1.86283000"],["88682.15000000","0.07339000"],["88682.73000000","0.04944000"],["88683.52000000","0.18046000"],["88686.00000000","0.00180000"],["88686.75000000","0.00000000"],["88686.93000000","0.00169000"],["88688.84000000","0.00000000"],["88689.02000000","0.00000000"],["88689.95000000","0.05084000"],["88690.60000000","0.00169000"],["88691.53000000","0.40642000"],["88691.63000000","0.20318000"],["88692.58000000","0.04200000"],["88692.59000000","0.04620000"],["88695.13000000","0.00008000"],["88695.25000000","0.04200000"],["88697.02000000","0.05460000"],["88697.74000000","0.00000000"],["88702.62000000","0.34335000"],["88706.14000000","0.00000000"],["88710.80000000","0.00000000"],["88711.91000000","0.00247000"],["88713.00000000","0.00000000"],["88720.98000000","0.03158000"],["88721.78000000","0.00717000"],["88721.86000000","0.00000000"],["88723.94000000","0.03156000"],["88731.69000000","0.00000000"],["88742.22000000","0.00600000"],["88743.86000000","0.08995000"],["88746.61000000","0.00000000"],["88748.33000000","0.10495000"],["88748.38000000","0.00000000"],["88754.81000000","0.00000000"],["88783.76000000","0.00000000"],["88799.99000000","0.00093000"],["88800.15000000","0.35037000"],["88861.57000000","0.00000000"],["88863.54000000","0.00000000"],["89019.72000000","0.00000000"],["89185.55000000","0.21928000"]]}
{"e":"depthUpdate","E":1767174257014,"s":"BTCUSDT","U":84208132938,"u":84208133240,"b":[["88651.00000000","6.38201000"],["88649.04000000","0.00257000"],["88648.56000000","0.00300000"],["88648.52000000","0.00006000"],["88647.05000000","0.37273000"],["88645.03000000","0.00000000"],["88644.21000000","0.20901000"],["88644.05000000","0.00000000"],["88640.77000000","0.05647000"],["88638.59000000","0.00056000"],["88635.05000000","0.00113000"],["88630.17000000","0.06345000"],["88625.14000000","0.00000000"],["88619.53000000","0.00000000"],["88614.98000000","0.03098000"],["88610.33000000","0.05460000"],["88590.00000000","0.14180000"],["88548.69000000","0.10495000"],["88494.26000000","0.00000000"],["88492.10000000","0.02368000"],["88459.98000000","5.13253000"],["88455.04000000","0.00000000"],["79785.90000000","0.00238000"],["79785.00000000","0.00534000"],["70920.80000000","0.00028000"],["33000.00000000","6.20342000"]],"a":[["88651.01000000","4.31588000"],["88651.02000000","0.00006000"],["88651.06000000","0.00000000"],["88651.07000000","0.00000000"],["88651.61000000","0.37293000"],["88652.03000000","0.00000000"],["88652.16000000","0.00097000"],["88652.30000000","0.00000000"],["88652.31000000","0.00000000"],["88652.35000000","0.00000000"],["88652.36000000","0.00000000"],["88652.39000000","0.00000000"],["88652.40000000","0.00000000"],["88652.44000000","0.00000000"],["88652.45000000","0.00000000"],["88652.53000000","0.00000000"],["88652.54000000","0.00000000"],["88652.57000000","0.00000000"],["88652.58000000","0.00000000"],["88652.62000000","0.00012000"],["88652.63000000","0.05672000"],["88652.64000000","0.02572000"],["88652.85000000","0.01125000"],["88652.99000000","0.00000000"],["88653.00000000","0.00000000"],["88653.04000000","0.00006000"],["88653.92000000","0.00000000"],["88655.32000000","0.00000000"],["88655.33000000","0.00000000"],["88657.67000000","0.00006000"],["88658.20000000","0.01140000"],["88659.44000000","0.06185000"],["88659.87000000","0.34249000"],["88660.59000000","0.00048000"],["88660.64000000","0.00188000"],["88663.42000000","0.00056000"],["88666.96000000","0.00113000"],["88672.84000000","0.00000000"],["88674.71000000","0.76219000"],["88676.40000000","1.24823000"],["88676.42000000","0.00000000"],["88685.41000000","0.00000000"],["88689.18000000","0.00169000"],["88690.60000000","0.00000000"],["88691.66000000","0.05256000"],["88692.54000000","0.03500000"],["88695.86000000","0.08455000"],["88696.94000000","0.05636000"],["88701.46000000","0.00000000"],["88701.59000000","0.00000000"],["88706.14000000","0.00000000"],["88710.00000000","0.14230000"],["88729.89000000","0.04360000"],["88743.12000000","0.00000000"],["88743.99000000","0.00000000"],["88839.15000000","0.00000000"],["88845.04000000","4.93359000"],["89179.71000000","0.21928000"],["89182.63000000","0.00075000"],["89185.55000000","0.00000000"]]}
{"e":"depthUpdate","E":1767174258014,"s":"BTCUSDT","U":84208133241,"u":84208133423,"b":[["88651.00000000","6.37110000"],["88650.98000000","0.00039000"],["88650.93000000","0.00012000"],["88650.92000000","0.05280000"],["88650.36000000","0.07546000"],["88650.27000000","0.03518000"],["88650.19000000","0.00000000"],["88650.18000000","0.00000000"],["88650.01000000","0.00000000"],["88648.76000000","0.02937000"],["88646.00000000","0.00106000"],["88645.58000000","0.00000000"],["88644.92000000","0.00000000"],["88641.64000000","0.00000000"],["88419.88000000","0.00000000"],["88365.88000000","0.00000000"],["86411.43000000","0.00000000"],["79785.90000000","0.00252000"],["79785.00000000","0.00534000"],["70921.00000000","0.00000000"],["70920.80000000","0.00028000"],["31914.36000000","0.00133000"]],"a":[["88651.01000000","4.26389000"],["88651.02000000","0.00012000"],["88651.61000000","0.37293000"],["88651.75000000","0.00012000"],["88651.76000000","0.05145000"],["88652.16000000","0.00006000"],["88652.62000000","0.00104000"],["88652.63000000","0.05660000"],["88652.64000000","0.02572000"],["88652.85000000","0.00000000"],["88653.05000000","0.00000000"],["88653.32000000","0.01134000"],["88659.44000000","0.06185000"],["88660.59000000","0.00000000"],["88660.64000000","0.00000000"],["88661.42000000","0.00012000"],["88666.47000000","0.00000000"],["88667.73000000","0.00347000"],["88669.86000000","0.05647000"],["88678.22000000","0.00000000"],["88682.13000000","0.98211000"],["88683.28000000","0.00000000"],["88696.50000000","0.40639000"],["89179.71000000","0.00000000"],["89182.63000000","0.22003000"]]}
{"e":"depthUpdate","E":1767174259014,"s":"BTCUSDT","U":84208133424,"u":84208133690,"b":[["88651.00000000","6.36496000"],["88650.99000000","0.00033000"],["88650.98000000","0.00039000"],["88650.92000000","0.05292000"],["88650.38000000","0.21397000"],["88649.97000000","0.00007000"],["88649.37000000","0.04218000"],["88649.33000000","0.37272000"],["88647.05000000","0.00000000"],["88646.00000000","0.00100000"],["88586.04000000","0.01000000"],["81558.93000000","0.00013000"],["79785.90000000","0.00238000"],["79785.00000000","0.00534000"],["70921.00000000","0.00000000"],["70920.80000000","0.00028000"],["60000.00000000","227.86147000"],["31914.36000000","0.00152000"]],"a":[["88651.01000000","3.13586000"],["88651.02000000","0.00006000"],["88651.51000000","0.14815000"],["88651.61000000","0.37311000"],["88651.75000000","0.00000000"],["88651.76000000","0.00000000"],["88652.15000000","0.00000000"],["88652.16000000","0.00018000"],["88652.17000000","0.05128000"],["88652.62000000","0.00113000"],["88652.63000000","0.05660000"],["88652.64000000","0.02572000"],["88653.09000000","0.00000000"],["88653.32000000","0.00000000"],["88653.38000000","0.00000000"],["88653.66000000","0.01130000"],["88659.44000000","0.06185000"],["88659.87000000","0.34249000"],["88660.60000000","0.00000000"],["88660.62000000","0.00000000"],["88660.63000000","0.00000000"],["88660.66000000","0.00048000"],["88660.67000000","0.00000000"],["88660.68000000","0.00000000"],["88660.71000000","0.00188000"],["88679.71000000","0.00169000"],["88686.93000000","0.00000000"],["88689.18000000","0.00000000"],["88729.89000000","0.00000000"],["88729.90000000","0.04360000"],["89179.71000000","0.00000000"],["89182.63000000","0.22003000"]]}
{"e":"depthUpdate","E":1767174260014,"s":"BTCUSDT","U":84208133691,"u":84208133812,"b":[["88651.00000000","6.37179000"],["88650.99000000","0.00033000"],["88650.98000000","0.00039000"],["88650.92000000","0.05292000"],["88650.38000000","0.21397000"],["88650.36000000","0.07540000"],["88650.35000000","0.00018000"],["88640.37000000","0.00000000"],["88608.64000000","0.20318000"],["88602.84000000","0.00000000"],["81558.93000000","0.00000000"],["79785.90000000","0.00252000"],["79785.00000000","0.00534000"],["70920.80000000","0.00028000"]],"a":[["88651.01000000","2.07696000"],["88651.02000000","0.00012000"],["88657.21000000","0.00000000"],["88658.20000000","0.01140000"],["88659.44000000","0.00000000"],["88659.45000000","0.06185000"],["88659.87000000","0.17087000"],["88660.99000000","0.06962000"],["88667.19000000","0.00000000"],["88667.73000000","0.00000000"],["88669.86000000","0.00000000"],["88670.38000000","0.05647000"],["88673.58000000","0.00347000"],["88676.99000000","0.00169000"],["88700.42000000","0.00000000"],["88705.09000000","0.01767000"],["88721.78000000","0.00000000"],["88738.36000000","0.03085000"],["88784.28000000","0.00000000"],["89179.71000000","0.00000000"],["89182.63000000","0.22003000"]]}
{"e":"depthUpdate","E":1767174261014,"s":"BTCUSDT","U":84208133813,"u":84208133914,"b":[["88651.00000000","6.37595000"],["88650.99000000","0.00033000"],["88650.98000000","0.00039000"],["88650.92000000","0.05292000"],["88650.38000000","0.21397000"],["88632.78000000","0.00000000"],["88631.59000000","0.04516000"],["88620.88000000","0.40674000"],["88602.33000000","0.00000000"],["88439.36000000","0.01767000"],["88351.00000000","0.00000000"],["79785.90000000","0.00238000"],["79785.00000000","0.00534000"],["70920.80000000","0.00028000"],["33000.00000000","6.20342000"],["31914.36000000","0.00171000"]],"a":[["88651.01000000","2.07367000"],["88670.26000000","0.00564000"],["88670.38000000","0.00000000"],["88671.45000000","0.05647000"],["88673.53000000","0.00346000"],["88673.58000000","0.00000000"],["88674.24000000","0.00000000"],["88679.22000000","0.00564000"],["88679.98000000","0.02823000"],["88681.58000000","0.00000000"],["88682.15000000","0.04516000"],["88692.16000000","0.01033000"],["88705.09000000","0.00000000"],["88805.20000000","0.00112000"],["88810.71000000","0.00000000"],["88951.01000000","0.00000000"]]}
{"e":"depthUpdate","E":1767174262014,"s":"BTCUSDT","U":84208133915,"u":84208134183,"b":[["88651.00000000","6.38410000"],["88650.99000000","0.00033000"],["88650.98000000","0.00039000"],["88650.92000000","0.05292000"],["88650.38000000","0.21397000"],["88649.04000000","0.00250000"],["88641.79000000","0.00000000"],["88641.12000000","0.00564000"],["88632.49000000","0.00000000"],["88627.12000000","0.00000000"],["79785.90000000","0.00252000"],["79785.00000000","0.00534000"],["70921.00000000","0.00000000"],["70920.80000000","0.00028000"]],"a":[["88651.01000000","2.06886000"],["88652.17000000","0.05128000"],["88652.62000000","0.00101000"],["88652.63000000","0.00012000"],["88652.64000000","0.02572000"],["88652.65000000","0.00000000"],["88652.66000000","0.00000000"],["88652.68000000","0.00000000"],["88652.69000000","0.00000000"],["88652.71000000","0.00000000"],["88652.72000000","0.00000000"],["88652.74000000","0.00000000"],["88652.75000000","0.00000000"],["88652.80000000","0.00000000"],["88652.81000000","0.00000000"],["88652.83000000","0.00000000"],["88652.84000000","0.00000000"],["88652.97000000","0.00000000"],["88652.98000000","0.00000000"],["88653.00000000","0.00000000"],["88653.01000000","0.00000000"],["88653.03000000","0.00006000"],["88653.04000000","0.05666000"],["88672.38000000","0.00169000"],["88678.79000000","0.40647000"],["88679.71000000","0.00000000"],["88679.98000000","0.00000000"],["88680.64000000","0.02823000"],["88696.50000000","0.00000000"],["89179.71000000","0.21928000"],["89182.63000000","0.00075000"]]}
{"e":"depthUpdate","E":1767174263016,"s":"BTCUSDT","U":84208134184,"u":84208134457,"b":[["88651.00000000","6.39233000"],["88650.99000000","0.00033000"],["88650.98000000","0.00039000"],["88650.93000000","0.00000000"],["88650.92000000","0.00000000"],["88650.38000000","0.11027000"],["88650.36000000","0.07549000"],["88650.01000000","0.00006000"],["88649.37000000","0.04218000"],["88649.33000000","0.00000000"],["88648.76000000","0.02949000"],["88647.71000000","0.00132000"],["88647.67000000","0.01104000"],["88646.83000000","0.37274000"],["88646.00000000","0.00106000"],["88631.58000000","0.00000000"],["88631.52000000","0.00000000"],["88622.39000000","0.04200000"],["88588.85000000","0.00182000"],["88586.04000000","0.00000000"],["88583.71000000","0.04200000"],["88578.35000000","0.04200000"],["88574.97000000","0.00000000"],["88513.82000000","0.00010000"],["81668.40000000","0.00007000"],["79785.90000000","0.00238000"],["79785.00000000","0.00534000"],["70921.00000000","0.00000000"],["70920.80000000","0.00028000"],["42000.00000000","16.04102000"],["31914.36000000","0.00190000"]],"a":[["88651.01000000","2.06964000"],["88652.17000000","0.05128000"],["88652.62000000","0.00000000"],["88652.64000000","0.02581000"],["88653.03000000","0.00000000"],["88653.04000000","0.00006000"],["88653.08000000","0.00000000"],["88653.09000000","0.00000000"],["88653.11000000","0.00000000"],["88653.12000000","0.00000000"],["88653.14000000","0.00000000"],["88653.15000000","0.00000000"],["88653.16000000","0.00000000"],["88653.17000000","0.00000000"],["88653.21000000","0.00000000"],["88653.22000000","0.00000000"],["88653.24000000","0.00000000"],["88653.25000000","0.00000000"],["88653.26000000","0.00000000"],["88653.27000000","0.00000000"],["88653.29000000","0.00006000"],["88653.30000000","0.05660000"],["88653.66000000","0.01227000"],["88659.45000000","0.06185000"],["88673.53000000","0.00000000"],["88673.59000000","0.00347000"],["88678.78000000","0.00564000"],["88679.22000000","0.00000000"],["88738.36000000","0.02368000"],["88738.78000000","0.00717000"],["88750.98000000","0.00056000"],["88760.40000000","0.00000000"]]}
